Workbook

Sheet 1-BRL PP Chart
A1: Data | C1: Mês | D1: Real (jul/94 a ago/26) | E1: Real (jul/94 a mar/25) | F1: Taxa de Inflação Mensal | G1: Taxa de Inflação Mensal | H1: Var. Anual | I1: Var. Anual
A2: 15615 | C2: 34486 | D2: =+'BRL e USD Chart'!$D2 -> 100 | E2: =+'BRL e USD Chart'!$D2 -> 100
A3: 15646 | C3: 34516 | D3: =+'BRL e USD Chart'!$D3 -> 93.597903 | E3: =+'BRL e USD Chart'!$D3 -> 93.597903 | F3: =+E3/E2-1 -> -0.064020966 | G3: =+F3 -> -0.064020966
A4: 15676 | C4: 34547 | D4: =+'BRL e USD Chart'!$D4 -> 91.888772 | E4: =+'BRL e USD Chart'!$D4 -> 91.888772 | F4: =+E4/E3-1 -> -0.018260357 | G4: =+F4 -> -0.018260357
A5: 15707 | C5: 34578 | D5: =+'BRL e USD Chart'!$D5 -> 90.50406 | E5: =+'BRL e USD Chart'!$D5 -> 90.50406 | F5: =+E5/E4-1 -> -0.015069438 | G5: =+F5 -> -0.015069438
A6: 15738 | C6: 34608 | D6: =+'BRL e USD Chart'!$D6 -> 88.193393 | E6: =+'BRL e USD Chart'!$D6 -> 88.193393 | F6: =+E6/E5-1 -> -0.025531086 | G6: =+F6 -> -0.025531086
A7: 15766 | C7: 34639 | D7: =+'BRL e USD Chart'!$D7 -> 85.782894 | E7: =+'BRL e USD Chart'!$D7 -> 85.782894 | F7: =+E7/E6-1 -> -0.027331972 | G7: =+F7 -> -0.027331972
A8: 15797 | C8: 34669 | D8: =+'BRL e USD Chart'!$D8 -> 84.340668 | E8: =+'BRL e USD Chart'!$D8 -> 84.340668 | F8: =+E8/E7-1 -> -0.016812506 | G8: =+F8 -> -0.016812506
A9: 15827 | C9: 34700 | D9: =+'BRL e USD Chart'!$D9 -> 82.930844 | E9: =+'BRL e USD Chart'!$D9 -> 82.930844 | F9: =+E9/E8-1 -> -0.016715831 | G9: =+F9 -> -0.016715831
A10: 15858 | C10: 34731 | D10: =+'BRL e USD Chart'!$D10 -> 82.093491 | E10: =+'BRL e USD Chart'!$D10 -> 82.093491 | F10: =+E10/E9-1 -> -0.01009701 | G10: =+F10 -> -0.01009701
A11: 15888 | C11: 34759 | D11: =+'BRL e USD Chart'!$D11 -> 80.840463 | E11: =+'BRL e USD Chart'!$D11 -> 80.840463 | F11: =+E11/E10-1 -> -0.015263417 | G11: =+F11 -> -0.015263417
A12: 15919 | C12: 34790 | D12: =+'BRL e USD Chart'!$D12 -> 78.922643 | E12: =+'BRL e USD Chart'!$D12 -> 78.922643 | F12: =+E12/E11-1 -> -0.023723519 | G12: =+F12 -> -0.023723519
A13: 15950 | C13: 34820 | D13: =+'BRL e USD Chart'!$D13 -> 76.870209 | E13: =+'BRL e USD Chart'!$D13 -> 76.870209 | F13: =+E13/E12-1 -> -0.026005649 | G13: =+F13 -> -0.026005649
A14: 15980 | C14: 34851 | D14: =+'BRL e USD Chart'!$D14 -> 75.171336 | E14: =+'BRL e USD Chart'!$D14 -> 75.171336 | F14: =+E14/E13-1 -> -0.022100528 | G14: =+F14 -> -0.022100528 | H14: =+E14/E2-1 -> -0.24828664 | I14: =+H14 -> -0.24828664
A15: 16011 | C15: 34881 | D15: =+'BRL e USD Chart'!$D15 -> 73.438195 | E15: =+'BRL e USD Chart'!$D15 -> 73.438195 | F15: =+E15/E14-1 -> -0.023055881 | G15: =+F15 -> -0.023055881 | H15: =+E15/E3-1 -> -0.21538633 | I15: =+H15 -> -0.21538633
A16: 16041 | C16: 34912 | D16: =+'BRL e USD Chart'!$D16 -> 72.718284 | E16: =+'BRL e USD Chart'!$D16 -> 72.718284 | F16: =+E16/E15-1 -> -0.0098029508 | G16: =+F16 -> -0.0098029508 | H16: =+E16/E4-1 -> -0.2086271 | I16: =+H16 -> -0.2086271
A17: 16072 | C17: 34943 | D17: =+'BRL e USD Chart'!$D17 -> 72.00543 | E17: =+'BRL e USD Chart'!$D17 -> 72.00543 | F17: =+E17/E16-1 -> -0.0098029508 | G17: =+F17 -> -0.0098029508 | H17: =+E17/E5-1 -> -0.20439558 | I17: =+H17 -> -0.20439558
A18: 16103 | C18: 34973 | D18: =+'BRL e USD Chart'!$D18 -> 71.00427 | E18: =+'BRL e USD Chart'!$D18 -> 71.00427 | F18: =+E18/E17-1 -> -0.013903954 | G18: =+F18 -> -0.013903954 | H18: =+E18/E6-1 -> -0.19490262 | I18: =+H18 -> -0.19490262
A19: 16132 | C19: 35004 | D19: =+'BRL e USD Chart'!$D19 -> 69.975628 | E19: =+'BRL e USD Chart'!$D19 -> 69.975628 | F19: =+E19/E18-1 -> -0.014487041 | G19: =+F19 -> -0.014487041 | H19: =+E19/E7-1 -> -0.1842706 | I19: =+H19 -> -0.1842706
A20: 16163 | C20: 35034 | D20: =+'BRL e USD Chart'!$D20 -> 68.900776 | E20: =+'BRL e USD Chart'!$D20 -> 68.900776 | F20: =+E20/E19-1 -> -0.015360378 | G20: =+F20 -> -0.015360378 | H20: =+E20/E8-1 -> -0.1830658 | I20: =+H20 -> -0.1830658
A21: 16193 | C21: 35065 | D21: =+'BRL e USD Chart'!$D21 -> 67.989714 | E21: =+'BRL e USD Chart'!$D21 -> 67.989714 | F21: =+E21/E20-1 -> -0.013222814 | G21: =+F21 -> -0.013222814 | H21: =+E21/E9-1 -> -0.18016373 | I21: =+H21 -> -0.18016373
A22: 16224 | C22: 35096 | D22: =+'BRL e USD Chart'!$D22 -> 67.296559 | E22: =+'BRL e USD Chart'!$D22 -> 67.296559 | F22: =+E22/E21-1 -> -0.010194992 | G22: =+F22 -> -0.010194992 | H22: =+E22/E10-1 -> -0.18024488 | I22: =+H22 -> -0.18024488
A23: 16254 | C23: 35125 | D23: =+'BRL e USD Chart'!$D23 -> 67.061843 | E23: =+'BRL e USD Chart'!$D23 -> 67.061843 | F23: =+E23/E22-1 -> -0.0034877927 | G23: =+F23 -> -0.0034877927 | H23: =+E23/E11-1 -> -0.17044213 | I23: =+H23 -> -0.17044213
A24: 16285 | C24: 35156 | D24: =+'BRL e USD Chart'!$D24 -> 66.227378 | E24: =+'BRL e USD Chart'!$D24 -> 66.227378 | F24: =+E24/E23-1 -> -0.012443215 | G24: =+F24 -> -0.012443215 | H24: =+E24/E12-1 -> -0.16085707 | I24: =+H24 -> -0.16085707
A25: 16316 | C25: 35186 | D25: =+'BRL e USD Chart'!$D25 -> 65.429142 | E25: =+'BRL e USD Chart'!$D25 -> 65.429142 | F25: =+E25/E24-1 -> -0.012052954 | G25: =+F25 -> -0.012052954 | H25: =+E25/E13-1 -> -0.14883615 | I25: =+H25 -> -0.14883615
... A376: 26999 | C376: 45870 | D376: =+'BRL e USD Chart'!$D376 -> 11.705162 | E376: =+'BRL e USD Chart'!$D376 -> 11.705162 | F376: =+E376/E375-1 -> 0.0011012113 | G376: =+F376 -> 0.0011012113 | H376: =+E376/E364-1 -> -0.048801259 | I376: =+H376 -> -0.048801259
A377: 27030 | C377: 45901 | D377: =+'BRL e USD Chart'!$D377 -> 11.649245 | E377: =+'BRL e USD Chart'!$D377 -> 11.649245
A378: 27061 | C378: 45931 | D378: =+'BRL e USD Chart'!$D378 -> 11.638771 | E378: =+'BRL e USD Chart'!$D378 -> 11.638771
A379: 27089 | C379: 45962 | D379: =+'BRL e USD Chart'!$D379 -> 11.617858 | E379: =+'BRL e USD Chart'!$D379 -> 11.617858
A380: 27120 | C380: 45992 | D380: =+'BRL e USD Chart'!$D380 -> 11.579646 | E380: =+'BRL e USD Chart'!$D380 -> 11.579646
A381: 27150 | C381: 46023 | D381: =+'BRL e USD Chart'!$D381 -> 11.541558 | E381: =+'BRL e USD Chart'!$D381 -> 11.541558
A382: 27181 | C382: 46054 | D382: =+'BRL e USD Chart'!$D382 -> 11.461329 | E382: =+'BRL e USD Chart'!$D382 -> 11.461329
A383: 27211 | C383: 46082 | D383: =+'BRL e USD Chart'!$D383 -> 11.361349 | E383: =+'BRL e USD Chart'!$D383 -> 11.361349
A384: 27242 | C384: 46113 | D384: =+'BRL e USD Chart'!$D384 -> 11.285735 | E384: =+'BRL e USD Chart'!$D384 -> 11.285735
A385: 27273 | C385: 46143 | D385: =+'BRL e USD Chart'!$D385 -> 11.220655 | E385: =+'BRL e USD Chart'!$D385 -> 11.220655
A386: 27303 | C386: 46174 | D386: =+'BRL e USD Chart'!$D386 -> 11.202731 | E386: =+'BRL e USD Chart'!$D386 -> 11.202731
A387: 27334 | C387: 46204 | D387: =+'BRL e USD Chart'!$D387 -> 11.194894 | E387: =+'BRL e USD Chart'!$D387 -> 11.194894
A388: 27364 | C388: 46235 | D388: =+'BRL e USD Chart'!$D388 -> 11.230833 | E388: =+'BRL e USD Chart'!$D388 -> 11.230833
A389: 27395
A390: 27426
...

Sheet 2-Chart Câmbio Justo
A1: Data | C1: Mês | D1: USDBRL | E1: USDBRL | F1: Câmbio pela PPC | G1: Cruzado (fev-86 a jan-89) | H1: Cruzado Novo (jan-89 a mar-90) | I1: Cruzeiro (mar-90 a ago/93) | J1: Cruzeiro real (ago/93 a jun-94) | K1: Real (jul/94 a jun-21)
A2: 15615 | C2: 34486 | D2: =+USDBRL!D499 -> 2292.9624 | E2: =+'USD PP 1994'!C989 -> 100 | F2: =+'BRL e USD Chart 99'!F2 -> 1 | G2: 100 | H2: 100 | I2: 100 | J2: 100 | K2: 100
A3: 15646 | C3: 34516 | D3: =+USDBRL!D500 -> 0.92905 | E3: =+'USD PP 1994'!C990 -> 99.704142 | F3: =+'BRL e USD Chart 99'!F3 -> 1.0652391 | G3: 98.202887 | H3: 87.711604 | I3: 83.201597 | J3: 74.560095 | K3: 93.501636 | P3: =5.2/4.9-1 -> 0.06122449
A4: 15676 | C4: 34547 | D4: =+USDBRL!D501 -> 0.8976 | E4: =+'USD PP 1994'!C991 -> 99.260355 | F4: =+'BRL e USD Chart 99'!F4 -> 1.0802229 | G4: 95.985619 | H4: 82.389258 | I4: 76.662303 | J4: 55.135765 | K4: 91.713228
A5: 15707 | C5: 34578 | D5: =+USDBRL!D502 -> 0.8642 | E5: =+'USD PP 1994'!C992 -> 98.964497 | F5: =+'BRL e USD Chart 99'!F5 -> 1.0934813 | G5: 94.177413 | H5: 74.88571 | I5: 68.632321 | J5: 40.588755 | K5: 90.967296
A6: 15738 | C6: 34608 | D6: =+USDBRL!D503 -> 0.845 | E6: =+'USD PP 1994'!C993 -> 98.964497 | F6: =+'BRL e USD Chart 99'!F6 -> 1.1221305 | G6: 93.281907 | H6: 64.22996 | I6: 61.65872 | J6: 29.301729 | K6: 88.172237
A7: 15766 | C7: 34639 | D7: =+USDBRL!D504 -> 0.8408 | E7: =+'USD PP 1994'!C994 -> 98.816568 | F7: =+'BRL e USD Chart 99'!F7 -> 1.1519379 | G7: 92.294357 | H7: 51.265033 | I7: 55.136117 | J7: 20.885053 | K7: 85.587494
A8: 15797 | C8: 34669 | D8: =+USDBRL!D505 -> 0.8491 | E8: =+'USD PP 1994'!C995 -> 98.816568 | F8: =+'BRL e USD Chart 99'!F8 -> 1.1716361 | G8: 90.591242 | H8: 40.032042 | I8: 48.736955 | J8: 15.113288 | K8: 84.530859
A9: 15827 | C9: 34700 | D9: =+USDBRL!D506 -> 0.8461 | E9: =+'USD PP 1994'!C996 -> 98.372781 | F9: =+'BRL e USD Chart 99'!F9 -> 1.1862026 | G9: 89.314051 | H9: 30.570479 | I9: 42.07628 | J9: 10.64766 | K9: 83.859979
A10: 15858 | C10: 34731 | D10: =+USDBRL!D507 -> 0.8398 | E10: =+'USD PP 1994'!C997 -> 98.076923 | F10: =+'BRL e USD Chart 99'!F10 -> 1.1946979 | G10: 86.645373 | H10: 22.506426 | I10: 35.48944 | J10: 7.2819448 | K10: 82.767448
A11: 15888 | C11: 34759 | D11: =+USDBRL!D508 -> 0.8884 | E11: =+'USD PP 1994'!C998 -> 97.633136 | F11: =+'BRL e USD Chart 99'!F11 -> 1.2077261 | G11: 82.969811 | H11: 16.393347 | I11: 30.586435 | J11: 5.0185698 | K11: 81.20825
A12: 15919 | C12: 34790 | D12: =+USDBRL!D509 -> 0.9065 | E12: =+'USD PP 1994'!C999 -> 97.337278 | F12: =+'BRL e USD Chart 99'!F12 -> 1.2333251 | G12: 75.22195 | H12: 11.467087 | I12: 25.273868 | J12: 3.3290679 | K12: 79.119495
A13: 15950 | C13: 34820 | D13: =+USDBRL!D510 -> 0.8964 | E13: =+'USD PP 1994'!C1000 -> 97.189349 | F13: =+'BRL e USD Chart 99'!F13 -> 1.2643305 | G13: 66.129187 | H13: 7.5530804 | I13: 20.967204 | K13: 77.590954
A14: 15980 | C14: 34851 | D14: =+USDBRL!D511 -> 0.913 | E14: =+'USD PP 1994'!C1001 -> 97.04142 | F14: =+'BRL e USD Chart 99'!F14 -> 1.2909365 | G14: 59.425941 | H14: 4.3276688 | I14: 19.508005 | K14: 75.580512
A15: 16011 | C15: 34881 | D15: =+USDBRL!D512 -> 0.9278 | E15: =+'USD PP 1994'!C1002 -> 97.04142 | F15: =+'BRL e USD Chart 99'!F15 -> 1.3214026 | G15: 53.073092 | H15: 2.5432939 | I15: 18.199464 | K15: 72.869757
A16: 16041 | C16: 34912 | D16: =+USDBRL!D513 -> 0.941 | E16: =+'USD PP 1994'!C1003 -> 96.745562 | F16: =+'BRL e USD Chart 99'!F16 -> 1.3304159 | G16: 45.536758 | H16: 1.419962 | I16: 17.208267 | K16: 71.84241
A17: 16072 | C17: 34943 | D17: =+USDBRL!D514 -> 0.9518 | E17: =+'USD PP 1994'!C1004 -> 96.597633 | F17: =+'BRL e USD Chart 99'!F17 -> 1.3415326 | G17: 36.000283 | I17: 15.67523 | K17: 71.314682
A18: 16103 | C18: 34973 | D18: =+USDBRL!D515 -> 0.9592 | E18: =+'USD PP 1994'!C1005 -> 96.301775 | F18: =+'BRL e USD Chart 99'!F18 -> 1.3562815 | G18: 28.40035 | I18: 14.083765 | K18: 70.274617
A19: 16132 | C19: 35004 | D19: =+USDBRL!D516 -> 0.9629 | E19: =+'USD PP 1994'!C1006 -> 96.301775 | F19: =+'BRL e USD Chart 99'!F19 -> 1.3762188 | G19: 25.998123 | I19: 12.308831 | K19: 69.461913
A20: 16163 | C20: 35034 | D20: =+USDBRL!D517 -> 0.9678 | E20: =+'USD PP 1994'!C1007 -> 96.301775 | F20: =+'BRL e USD Chart 99'!F20 -> 1.3976878 | G20: 24.890496 | I20: 10.591886 | K20: 68.631472
A21: 16193 | C21: 35065 | D21: =+USDBRL!D518 -> 0.974 | E21: =+'USD PP 1994'!C1008 -> 95.857988 | F21: =+'BRL e USD Chart 99'!F21 -> 1.4098896 | G21: 23.320993 | I21: 8.4620008 | K21: 67.404707
A22: 16224 | C22: 35096 | D22: =+USDBRL!D519 -> 0.9806 | E22: =+'USD PP 1994'!C1009 -> 95.414201 | F22: =+'BRL e USD Chart 99'!F22 -> 1.4178169 | G22: 21.168188 | I22: 6.7485452 | K22: 67.136162
A23: 16254 | C23: 35125 | D23: =+USDBRL!D520 -> 0.9857 | E23: =+'USD PP 1994'!C1010 -> 94.970414 | F23: =+'BRL e USD Chart 99'!F23 -> 1.4161617 | G23: 18.666833 | I23: 5.475493 | K23: 66.982103
A24: 16285 | C24: 35156 | D24: =+USDBRL!D521 -> 0.9898 | E24: =+'USD PP 1994'!C1011 -> 94.674556 | F24: =+'BRL e USD Chart 99'!F24 -> 1.429538 | G24: 16.103203 | I24: 4.3494265 | K24: 65.914292
A25: 16316 | C25: 35186 | D25: =+USDBRL!D522 -> 0.9949 | E25: =+'USD PP 1994'!C1012 -> 94.526627 | F25: =+'BRL e USD Chart 99'!F25 -> 1.4447175 | G25: 14.03941 | I25: 3.5777137 | K25: 65.042719
A26: 16346 | C26: 35217 | D26: =+USDBRL!D523 -> 1.0009 | E26: =+'USD PP 1994'!C1013 -> 94.378698 | F26: =+'BRL e USD Chart 99'!F26 -> 1.4596218 | G26: 12.382616 | I26: 2.9388152 | K26: 64.138368
A27: 16377 | C27: 35247 | D27: =+USDBRL!D524 -> 1.0065 | E27: =+'USD PP 1994'!C1014 -> 94.230769 | F27: =+'BRL e USD Chart 99'!F27 -> 1.4735104 | G27: 10.436254 | I27: 2.394537 | K27: 63.30902
A28: 16407 | C28: 35278 | D28: =+USDBRL!D525 -> 1.013 | E28: =+'USD PP 1994'!C1015 -> 94.08284 | F28: =+'BRL e USD Chart 99'!F28 -> 1.4776705 | G28: 8.6129027 | I28: 1.9542455 | K28: 63.094499
... A36: 16650 | C36: 35521 | D36: =+USDBRL!D533 -> 1.0605 | E36: =+'USD PP 1994'!C1023 -> 92.307692 | F36: =+'BRL e USD Chart 99'!F36 -> 1.5134078 | G36: 1.6238485 | I36: 0.34952315 | K36: 61.084333
A37: 16681 | C37: 35551 | D37: =+USDBRL!D534 -> 1.0679 | E37: =+'USD PP 1994'!C1024 -> 92.455621 | F37: =+'BRL e USD Chart 99'!F37 -> 1.5220481 | G37: =+USDBRL!D534/'2-Chart Câmbio Justo'!F37*100 -> 70.162042 | I37: 0.27939501 | K37: 60.750207
A38: 16711 | C38: 35582 | D38: =+USDBRL!D535 -> 1.0742 | E38: =+'USD PP 1994'!C1025 -> 92.307692 | F38: =+'BRL e USD Chart 99'!F38 -> 1.5278187 | G38: =+USDBRL!D535/'2-Chart Câmbio Justo'!F38*100 -> 70.30939 | I38: 0.22323027 | K38: 59.899632
A39: 16742 | C39: 35612 | D39: =+USDBRL!D536 -> 1.0803 | E39: =+'USD PP 1994'!C1026 -> 92.159763 | F39: =+'BRL e USD Chart 99'!F39 -> 1.5287261 | G39: =+USDBRL!D536/'2-Chart Câmbio Justo'!F39*100 -> 70.666682 | I39: 0.1733962 | K39: 59.833815
A40: 16772 | C40: 35643 | D40: =+USDBRL!D537 -> 1.0875 | E40: =+'USD PP 1994'!C1027 -> 92.011834 | F40: =+'BRL e USD Chart 99'!F40 -> 1.525967 | G40: =+USDBRL!D537/'2-Chart Câmbio Justo'!F40*100 -> 71.266285 | I40: 0.13426994 | K40: 60.292035
A41: 16803 | C41: 35674 | D41: =+USDBRL!D538 -> 1.0932 | E41: =+'USD PP 1994'!C1028 -> 91.715976 | F41: =+'BRL e USD Chart 99'!F41 -> 1.521973 | G41: =+USDBRL!D538/'2-Chart Câmbio Justo'!F41*100 -> 71.827818 | I41: 0.1028652 | K41: 60.286006
A42: 16834 | C42: 35704 | D42: =+USDBRL!D539 -> 1.0997 | E42: =+'USD PP 1994'!C1029 -> 91.568047 | F42: =+'BRL e USD Chart 99'!F42 -> 1.5230131 | G42: =+USDBRL!D539/'2-Chart Câmbio Justo'!F42*100 -> 72.205551 | I42: 0.078589041 | K42: 60.153668
A43: 16862 | C43: 35735 | D43: =+USDBRL!D540 -> 1.1069 | E43: =+'USD PP 1994'!C1030 -> 91.568047 | F43: =+'BRL e USD Chart 99'!F43 -> 1.5256022 | G43: =+USDBRL!D540/'2-Chart Câmbio Justo'!F43*100 -> 72.554955 | I43: 0.058661671 | K43: 59.836534
A44: 16893 | C44: 35765 | D44: =+USDBRL!D541 -> 1.1132 | E44: =+'USD PP 1994'!C1031 -> 91.715976 | F44: =+'BRL e USD Chart 99'!F44 -> 1.5346375 | G44: =+USDBRL!D541/'2-Chart Câmbio Justo'!F44*100 -> 72.538301 | K44: 59.497399
A45: 16923 | C45: 35796 | D45: =+USDBRL!D542 -> 1.1195 | E45: =+'USD PP 1994'!C1032 -> 91.568047 | F45: =+'BRL e USD Chart 99'!F45 -> 1.5430407 | G45: =+USDBRL!D542/'2-Chart Câmbio Justo'!F45*100 -> 72.551555 | K45: 59.354947
A46: 16954 | C46: 35827 | D46: =+USDBRL!D543 -> 1.1267 | E46: =+'USD PP 1994'!C1033 -> 91.420118 | F46: =+'BRL e USD Chart 99'!F46 -> 1.5476344 | G46: =+USDBRL!D543/'2-Chart Câmbio Justo'!F46*100 -> 72.801432 | K46: 59.450067
A47: 16984 | C47: 35855 | D47: =+USDBRL!D544 -> 1.1333 | E47: =+'USD PP 1994'!C1034 -> 91.272189 | F47: =+'BRL e USD Chart 99'!F47 -> 1.5503836 | G47: =+USDBRL!D544/'2-Chart Câmbio Justo'!F47*100 -> 73.09804 | K47: 59.587118
...

Sheet 3-BRL USD 99 Depr %
A1: Data | B1: Sobre/(Sub)Valorização do BRL | C1: Sobre/(Sub)Valorização do BRL | D1: BTC | E1: Média Histórica | F1: Média Móvel 5 anos
A2: 34516
A3: 34547
A4: 34578
A5: 34608
A6: 34639
A7: 34669
A8: 34700
A9: 34731
A10: 34759
A11: 34790
A12: 34820
A13: 34851
... A57: 36192
A58: 36220 | B58: =+'BRL e USD Chart 99'!F59/USDBRL!D556-1 -> -0.00034095668 | C58: =+B58 -> -0.00034095668 | E58: =AVERAGE($C$58:$C$381) -> 0.16263388
A59: 36251 | B59: =+'BRL e USD Chart 99'!F60/USDBRL!D557-1 -> 0.11813564 | C59: =+B59 -> 0.11813564 | E59: =AVERAGE($C$58:$C$381) -> 0.16263388
A60: 36281 | B60: =+'BRL e USD Chart 99'!F61/USDBRL!D558-1 -> 0.12855308 | C60: =+B60 -> 0.12855308 | E60: =AVERAGE($C$58:$C$381) -> 0.16263388
A61: 36312 | B61: =+'BRL e USD Chart 99'!F62/USDBRL!D559-1 -> 0.078230413 | C61: =+B61 -> 0.078230413 | E61: =AVERAGE($C$58:$C$381) -> 0.16263388
A62: 36342 | B62: =+'BRL e USD Chart 99'!F63/USDBRL!D560-1 -> 0.065297397 | C62: =+B62 -> 0.065297397 | E62: =AVERAGE($C$58:$C$381) -> 0.16263388
A63: 36373 | B63: =+'BRL e USD Chart 99'!F64/USDBRL!D561-1 -> 0.022011415 | C63: =+B63 -> 0.022011415 | E63: =AVERAGE($C$58:$C$381) -> 0.16263388
A64: 36404 | B64: =+'BRL e USD Chart 99'!F65/USDBRL!D562-1 -> 0.012409449 | C64: =+B64 -> 0.012409449 | E64: =AVERAGE($C$58:$C$381) -> 0.16263388
A65: 36434 | B65: =+'BRL e USD Chart 99'!F66/USDBRL!D563-1 -> -0.016003041 | C65: =+B65 -> -0.016003041 | E65: =AVERAGE($C$58:$C$381) -> 0.16263388
A66: 36465 | B66: =+'BRL e USD Chart 99'!F67/USDBRL!D564-1 -> 0.013731797 | C66: =+B66 -> 0.013731797 | E66: =AVERAGE($C$58:$C$381) -> 0.16263388
A67: 36495 | B67: =+'BRL e USD Chart 99'!F68/USDBRL!D565-1 -> 0.068026202 | C67: =+B67 -> 0.068026202 | E67: =AVERAGE($C$58:$C$381) -> 0.16263388
A68: 36526 | B68: =+'BRL e USD Chart 99'!F69/USDBRL!D566-1 -> 0.09425219 | C68: =+B68 -> 0.09425219 | E68: =AVERAGE($C$58:$C$381) -> 0.16263388
A69: 36557 | B69: =+'BRL e USD Chart 99'!F70/USDBRL!D567-1 -> 0.10756525 | C69: =+B69 -> 0.10756525 | E69: =AVERAGE($C$58:$C$381) -> 0.16263388
... A105: 37653 | B105: =+'BRL e USD Chart 99'!F106/USDBRL!D603-1 -> -0.32820591 | C105: =+B105 -> -0.32820591 | E105: =AVERAGE($C$58:$C$381) -> 0.16263388
A106: 37681 | B106: =+'BRL e USD Chart 99'!F107/USDBRL!D604-1 -> -0.29544135 | C106: =+B106 -> -0.29544135 | E106: =AVERAGE($C$58:$C$381) -> 0.16263388 | F106: =AVERAGE(B58:B106) -> -0.072144009
A107: 37712 | B107: =+'BRL e USD Chart 99'!F108/USDBRL!D605-1 -> -0.21228527 | C107: =+B107 -> -0.21228527 | E107: =AVERAGE($C$58:$C$381) -> 0.16263388 | F107: =AVERAGE(B59:B107) -> -0.076469404
A108: 37742 | B108: =+'BRL e USD Chart 99'!F109/USDBRL!D606-1 -> -0.16223148 | C108: =+B108 -> -0.16223148 | E108: =AVERAGE($C$58:$C$381) -> 0.16263388 | F108: =AVERAGE(B60:B108) -> -0.082191181
A109: 37773 | B109: =+'BRL e USD Chart 99'!F110/USDBRL!D607-1 -> -0.14402404 | C109: =+B109 -> -0.14402404 | E109: =AVERAGE($C$58:$C$381) -> 0.16263388 | F109: =AVERAGE(B61:B109) -> -0.08775398
A110: 37803 | B110: =+'BRL e USD Chart 99'!F111/USDBRL!D608-1 -> -0.14129933 | C110: =+B110 -> -0.14129933 | E110: =AVERAGE($C$58:$C$381) -> 0.16263388 | F110: =AVERAGE(B62:B110) -> -0.092234179
A111: 37834 | B111: =+'BRL e USD Chart 99'!F112/USDBRL!D609-1 -> -0.17663362 | C111: =+B111 -> -0.17663362 | E111: =AVERAGE($C$58:$C$381) -> 0.16263388 | F111: =AVERAGE(B63:B111) -> -0.097171546
A112: 37865 | B112: =+'BRL e USD Chart 99'!F113/USDBRL!D610-1 -> -0.15072673 | C112: =+B112 -> -0.15072673 | E112: =AVERAGE($C$58:$C$381) -> 0.16263388 | F112: =AVERAGE(B64:B112) -> -0.10069681
A113: 37895 | B113: =+'BRL e USD Chart 99'!F114/USDBRL!D611-1 -> -0.13001512 | C113: =+B113 -> -0.13001512 | E113: =AVERAGE($C$58:$C$381) -> 0.16263388 | F113: =AVERAGE(B65:B113) -> -0.10360344
A114: 37926 | B114: =+'BRL e USD Chart 99'!F115/USDBRL!D612-1 -> -0.13955275 | C114: =+B114 -> -0.13955275 | E114: =AVERAGE($C$58:$C$381) -> 0.16263388 | F114: =AVERAGE(B66:B114) -> -0.10612486
A115: 37956 | B115: =+'BRL e USD Chart 99'!F116/USDBRL!D613-1 -> -0.13688956 | C115: =+B115 -> -0.13688956 | E115: =AVERAGE($C$58:$C$381) -> 0.16263388 | F115: =AVERAGE(B67:B115) -> -0.10919877
A116: 37987 | B116: =+'BRL e USD Chart 99'!F117/USDBRL!D614-1 -> -0.11284126 | C116: =+B116 -> -0.11284126 | E116: =AVERAGE($C$58:$C$381) -> 0.16263388 | F116: =AVERAGE(B68:B116) -> -0.11288994
A117: 38018 | B117: =+'BRL e USD Chart 99'!F118/USDBRL!D615-1 -> -0.13616985 | C117: =+B117 -> -0.13616985 | E117: =AVERAGE($C$58:$C$381) -> 0.16263388 | F117: =AVERAGE(B69:B117) -> -0.11759243
... A376: 45901 | B376: =+'BRL e USD Chart 99'!F377/USDBRL!D874-1 -> -0.11933002 | C376: =+B376 -> -0.11933002 | E376: =AVERAGE($C$58:$C$381) -> 0.16263388 | F376: =AVERAGE(B328:B376) -> -0.12876646
...

Sheet USDBRL
A1: Data | B1: 3697 - Taxa de câmbio - Livre - Dólar americano (compra) - Média de período - mensal - u.m.c./US$ | C1: 3698 - Taxa de câmbio - Livre - Dólar americano (venda) - Média de período - mensal - u.m.c./US$ | D1: USDBRL
A2: 19360 | B2: 18.38 | C2: 18.72 | D2: =(B2+C2)/2 -> 18.55
A3: 19391 | B3: 36.5 | C3: 38 | D3: =(B3+C3)/2 -> 37.25
A4: 19419 | B4: 36.7903 | C4: 38.2581 | D4: =(B4+C4)/2 -> 37.5242
A5: 19450 | B5: 40.93 | C5: 41.9333 | D5: =(B5+C5)/2 -> 41.43165
A6: 19480 | B6: 39.2581 | C6: 40.2581 | D6: =(B6+C6)/2 -> 39.7581
A7: 19511 | B7: 43.0933 | C7: 44.07 | D7: =(B7+C7)/2 -> 43.58165
A8: 19541 | B8: 43.5774 | C8: 44.38 | D8: =(B8+C8)/2 -> 43.9787
A9: 19572 | B9: 39.6677 | C9: 40.6677 | D9: =(B9+C9)/2 -> 40.1677
A10: 19603 | B10: 37.4867 | C10: 38.4867 | D10: =(B10+C10)/2 -> 37.9867
A11: 19633 | B11: 37.1 | C11: 38.1 | D11: =(B11+C11)/2 -> 37.6
A12: 19664 | B12: 37.5633 | C12: 38.5967 | D12: =(B12+C12)/2 -> 38.08
A13: 19694 | B13: 51.1129 | C13: 53.0968 | D13: =(B13+C13)/2 -> 52.10485
... A887: 46309 | B887: 4.9859 | C887: 4.9853 | D887: =(B887+C887)/2 -> 4.9856

Sheet BRL IPCA
A1: Data | B1: 193 - Índice de preços ao consumidor-São Paulo (IPC-Fipe) - Var. % mensal | C1: Cruzeiro (nov/42 a jan/67 | D1: Cruzeiro Novo (fev-67 a mai-70) | E1: Cruzeiro (jun-70 a fev-86) | F1: Cruzado (mar-86 a dez-88) | G1: Cruzado Novo (jan-89 a fev-90) | H1: Cruzeiro (mar-90 a jul/93) | I1: Cruzeiro Real (ago/93 a jun-94) | J1: Real (jul/94 a jun-21) | K1: Cruzeiro (nov/42 a jan/67 | L1: Cruzeiro Novo (fev-67 a mai-70) | M1: Cruzeiro (jun-70 a fev-86) | N1: Cruzado (mar-86 a dez-88) | O1: Cruzado Novo (jan-89 a fev-90) | P1: Cruzeiro (mar-90 a jul/93) | Q1: Cruzeiro Real (ago/93 a jun-94) | R1: Real (jul/94 a jun-21) | S1: Cruzeiro (nov/42 a jan/67 | T1: Cruzeiro Novo (fev-67 a mai-70) | U1: Cruzeiro (jun-70 a fev-86) | V1: Cruzado (mar-86 a dez-88) | W1: Cruzado Novo (jan-89 a fev-90) | X1: Cruzeiro (mar-90 a jul/93) | Y1: Cruzeiro Real (ago/93 a jun-94) | Z1: Real (jul/94 a jun-21) | AA1: 433 - Índice nacional de preços ao consumidor-amplo (IPCA) - Var. % mensal | AB1: 1788 - BM - Base monetária restrita (saldo em final de período) - u.m.c. (mil) | AC1: 1827 - Meios de pagamento - M1 (saldo em final de período) - u.m.c. (mil) | AD1: 1837 - Meios de pagamento amplos - M2 (saldo em final de período) - u.m.c. (mil)
A2: 14277 | B2: -0.0152 | AA2: - | AB2: - | AC2: - | AD2: -
A3: 14305 | B3: 0.0248 | AA3: - | AB3: - | AC3: - | AD3: -
A4: 14336 | B4: 0.0181 | AA4: - | AB4: - | AC4: - | AD4: -
A5: 14366 | B5: 0 | AA5: - | AB5: - | AC5: - | AD5: -
A6: 14397 | B6: -0.003 | AA6: - | AB6: - | AC6: - | AD6: -
A7: 14427 | B7: -0.0089 | AA7: - | AB7: - | AC7: - | AD7: -
A8: 14458 | B8: 0.007 | AA8: - | AB8: - | AC8: - | AD8: -
A9: 14489 | B9: -0.0099 | AA9: - | AB9: - | AC9: - | AD9: -
A10: 14519 | B10: 0.0131 | AA10: - | AB10: - | AC10: - | AD10: -
A11: 14550 | B11: 0.003 | AA11: - | AB11: - | AC11: - | AD11: -
A12: 14580 | B12: -0.0138 | AA12: - | AB12: - | AC12: - | AD12: -
A13: 14611 | B13: 0.0481 | AA13: - | AB13: - | AC13: - | AD13: -
... A45: 15585 | B45: 0.0208 | AA45: - | AB45: - | AC45: - | AD45: -
A46: 15615 | B46: -0.012 | C46: 100 | K46: 100 | AA46: - | AB46: - | AC46: - | AD46: -
A47: 15646 | B47: 0.0028 | C47: =+$C$46/(1+((K47/100)-1)) -> 99.720782 | K47: =+K46*(1+S47) -> 100.28 | S47: 0.0028 | AA47: - | AB47: - | AC47: - | AD47: -
A48: 15676 | B48: -0.0021 | C48: =+$C$46/(1+((K48/100)-1)) -> 99.930636 | K48: =+K47*(1+S48) -> 100.06941 | S48: -0.0021 | AA48: - | AB48: - | AC48: - | AD48: -
A49: 15707 | B49: 0.0185 | C49: =+$C$46/(1+((K49/100)-1)) -> 98.115499 | K49: =+K48*(1+S49) -> 101.9207 | S49: 0.0185 | AA49: - | AB49: - | AC49: - | AD49: -
A50: 15738 | B50: 0.014 | C50: =+$C$46/(1+((K50/100)-1)) -> 96.760848 | K50: =+K49*(1+S50) -> 103.34759 | S50: 0.014 | AA50: - | AB50: - | AC50: - | AD50: -
A51: 15766 | B51: -0.0014 | C51: =+$C$46/(1+((K51/100)-1)) -> 96.896503 | K51: =+K50*(1+S51) -> 103.2029 | S51: -0.0014 | AA51: - | AB51: - | AC51: - | AD51: -
A52: 15797 | B52: 0.0311 | C52: =+$C$46/(1+((K52/100)-1)) -> 93.973914 | K52: =+K51*(1+S52) -> 106.41251 | S52: 0.0311 | AA52: - | AB52: - | AC52: - | AD52: -
A53: 15827 | B53: 0.004 | C53: =+$C$46/(1+((K53/100)-1)) -> 93.599516 | K53: =+K52*(1+S53) -> 106.83816 | S53: 0.004 | AA53: - | AB53: - | AC53: - | AD53: -
A54: 15858 | B54: -0.0047 | C54: =+$C$46/(1+((K54/100)-1)) -> 94.041511 | K54: =+K53*(1+S54) -> 106.33602 | S54: -0.0047 | AA54: - | AB54: - | AC54: - | AD54: -
A55: 15888 | B55: 0.0308 | C55: =+$C$46/(1+((K55/100)-1)) -> 91.231578 | K55: =+K54*(1+S55) -> 109.61117 | S55: 0.0308 | AA55: - | AB55: - | AC55: - | AD55: -
A56: 15919 | B56: 0.0019 | C56: =+$C$46/(1+((K56/100)-1)) -> 91.058567 | K56: =+K55*(1+S56) -> 109.81943 | S56: 0.0019 | AA56: - | AB56: - | AC56: - | AD56: -
A57: 15950 | B57: 0.0208 | C57: =+$C$46/(1+((K57/100)-1)) -> 89.203142 | K57: =+K56*(1+S57) -> 112.10367 | S57: 0.0208 | AA57: - | AB57: - | AC57: - | AD57: -
A58: 15980 | B58: 0.0419 | C58: =+$C$46/(1+((K58/100)-1)) -> 85.615838 | K58: =+K57*(1+S58) -> 116.80082 | S58: 0.0419 | AA58: - | AB58: - | AC58: - | AD58: -
... A84: 16772 | B84: -0.0008 | C84: =+$C$46/(1+((K84/100)-1)) -> 53.143297 | K84: =+K83*(1+S84) -> 188.17049 | S84: -0.0008 | AA84: - | AB84: - | AC84: - | AD84: -
A85: 16803 | B85: -0.0314 | C85: =+$C$46/(1+((K85/100)-1)) -> 54.866092 | K85: =+K84*(1+S85) -> 182.26193 | S85: -0.0314 | AA85: - | AB85: 22900000 | AC85: 39600000 | AD85: -
A86: 16834 | B86: 0.0211 | C86: =+$C$46/(1+((K86/100)-1)) -> 53.73234 | K86: =+K85*(1+S86) -> 186.10766 | S86: 0.0211 | AA86: - | AB86: 23600000 | AC86: 39300000 | AD86: -
A87: 16862 | B87: 0.0829 | C87: =+$C$46/(1+((K87/100)-1)) -> 49.61893 | K87: =+K86*(1+S87) -> 201.53598 | S87: 0.0829 | AA87: - | AB87: 23900000 | AC87: 38600000 | AD87: -
A88: 16893 | B88: 0.0134 | C88: =+$C$46/(1+((K88/100)-1)) -> 48.962829 | K88: =+K87*(1+S88) -> 204.23657 | S88: 0.0134 | AA88: - | AB88: 23700000 | AC88: 42000000 | AD88: -
A89: 16923 | B89: 0.016 | C89: =+$C$46/(1+((K89/100)-1)) -> 48.19176 | K89: =+K88*(1+S89) -> 207.50435 | S89: 0.016 | AA89: - | AB89: 24200000 | AC89: 42700000 | AD89: -
A90: 16954 | B90: 0.0199 | C90: =+$C$46/(1+((K90/100)-1)) -> 47.251456 | K90: =+K89*(1+S90) -> 211.63369 | S90: 0.0199 | AA90: - | AB90: 24900000 | AC90: 43400000 | AD90: -
A91: 16984 | B91: 0.0336 | C91: =+$C$46/(1+((K91/100)-1)) -> 45.715418 | K91: =+K90*(1+S91) -> 218.74458 | S91: 0.0336 | AA91: - | AB91: 25500000 | AC91: 43800000 | AD91: -
A92: 17015 | B92: 0.0286 | C92: =+$C$46/(1+((K92/100)-1)) -> 44.444311 | K92: =+K91*(1+S92) -> 225.00068 | S92: 0.0286 | AA92: - | AB92: 25700000 | AC92: 44900000 | AD92: -
A93: 17046 | B93: -0.0246 | C93: =+$C$46/(1+((K93/100)-1)) -> 45.565215 | K93: =+K92*(1+S93) -> 219.46566 | S93: -0.0246 | AA93: - | AB93: 25700000 | AC93: 45300000 | AD93: -
A94: 17076 | B94: 0.0104 | C94: =+$C$46/(1+((K94/100)-1)) -> 45.096215 | K94: =+K93*(1+S94) -> 221.7481 | S94: 0.0104 | AA94: - | AB94: 25600000 | AC94: 45400000 | AD94: -
A95: 17107 | B95: 0.0128 | C95: =+$C$46/(1+((K95/100)-1)) -> 44.526278 | K95: =+K94*(1+S95) -> 224.58648 | S95: 0.0128 | AA95: - | AB95: 25300000 | AC95: 45800000 | AD95: -
A96: 17137 | B96: -0.0032 | C96: =+$C$46/(1+((K96/100)-1)) -> 44.66922 | K96: =+K95*(1+S96) -> 223.8678 | S96: -0.0032 | AA96: - | AB96: 25700000 | AC96: 45400000 | AD96: -
...

Sheet BRL e USD Chart
A1: Data | C1: Mês | D1: Real (jul/94 a set/23) | E1: Dólar (jul/94 a set/23) | F1: Câmbio pela PPC | G1: Cruzado (fev-86 a jan-89) | H1: Cruzado Novo (jan-89 a mar-90) | I1: Cruzeiro (mar-90 a ago/93) | J1: Cruzeiro real (ago/93 a jun-94) | K1: Real (jul/94 a jun-21)
A2: 15615 | C2: 34486 | D2: 100 | E2: =+'USD PP 1994'!C989 -> 100 | F2: =+E2/D2 -> 1 | G2: 100 | H2: 100 | I2: 100 | J2: 100 | K2: 100
A3: 15646 | C3: 34516 | D3: 93.597903 | E3: =+'USD PP 1994'!C990 -> 99.704142 | F3: =+E3/D3 -> 1.0652391 | G3: 98.202887 | H3: 87.711604 | I3: 83.201597 | J3: 74.560095 | K3: 93.501636 | P3: =5.2/4.9-1 -> 0.06122449
A4: 15676 | C4: 34547 | D4: 91.888772 | E4: =+'USD PP 1994'!C991 -> 99.260355 | F4: =+E4/D4 -> 1.0802229 | G4: 95.985619 | H4: 82.389258 | I4: 76.662303 | J4: 55.135765 | K4: 91.713228
A5: 15707 | C5: 34578 | D5: 90.50406 | E5: =+'USD PP 1994'!C992 -> 98.964497 | F5: =+E5/D5 -> 1.0934813 | G5: 94.177413 | H5: 74.88571 | I5: 68.632321 | J5: 40.588755 | K5: 90.967296
A6: 15738 | C6: 34608 | D6: 88.193393 | E6: =+'USD PP 1994'!C993 -> 98.964497 | F6: =+E6/D6 -> 1.1221305 | G6: 93.281907 | H6: 64.22996 | I6: 61.65872 | J6: 29.301729 | K6: 88.172237
A7: 15766 | C7: 34639 | D7: 85.782894 | E7: =+'USD PP 1994'!C994 -> 98.816568 | F7: =+E7/D7 -> 1.1519379 | G7: 92.294357 | H7: 51.265033 | I7: 55.136117 | J7: 20.885053 | K7: 85.587494
A8: 15797 | C8: 34669 | D8: 84.340668 | E8: =+'USD PP 1994'!C995 -> 98.816568 | F8: =+E8/D8 -> 1.1716361 | G8: 90.591242 | H8: 40.032042 | I8: 48.736955 | J8: 15.113288 | K8: 84.530859
A9: 15827 | C9: 34700 | D9: 82.930844 | E9: =+'USD PP 1994'!C996 -> 98.372781 | F9: =+E9/D9 -> 1.1862026 | G9: 89.314051 | H9: 30.570479 | I9: 42.07628 | J9: 10.64766 | K9: 83.859979
A10: 15858 | C10: 34731 | D10: 82.093491 | E10: =+'USD PP 1994'!C997 -> 98.076923 | F10: =+E10/D10 -> 1.1946979 | G10: 86.645373 | H10: 22.506426 | I10: 35.48944 | J10: 7.2819448 | K10: 82.767448
A11: 15888 | C11: 34759 | D11: 80.840463 | E11: =+'USD PP 1994'!C998 -> 97.633136 | F11: =+E11/D11 -> 1.2077261 | G11: 82.969811 | H11: 16.393347 | I11: 30.586435 | J11: 5.0185698 | K11: 81.20825
A12: 15919 | C12: 34790 | D12: 78.922643 | E12: =+'USD PP 1994'!C999 -> 97.337278 | F12: =+E12/D12 -> 1.2333251 | G12: 75.22195 | H12: 11.467087 | I12: 25.273868 | J12: 3.3290679 | K12: 79.119495
A13: 15950 | C13: 34820 | D13: 76.870209 | E13: =+'USD PP 1994'!C1000 -> 97.189349 | F13: =+E13/D13 -> 1.2643305 | G13: 66.129187 | H13: 7.5530804 | I13: 20.967204 | K13: 77.590954
A14: 15980 | C14: 34851 | D14: 75.171336 | E14: =+'USD PP 1994'!C1001 -> 97.04142 | F14: =+E14/D14 -> 1.2909365 | G14: 59.425941 | H14: 4.3276688 | I14: 19.508005 | K14: 75.580512
A15: 16011 | C15: 34881 | D15: 73.438195 | E15: =+'USD PP 1994'!C1002 -> 97.04142 | F15: =+E15/D15 -> 1.3214026 | G15: 53.073092 | H15: 2.5432939 | I15: 18.199464 | K15: 72.869757
A16: 16041 | C16: 34912 | D16: 72.718284 | E16: =+'USD PP 1994'!C1003 -> 96.745562 | F16: =+E16/D16 -> 1.3304159 | G16: 45.536758 | H16: 1.419962 | I16: 17.208267 | K16: 71.84241
A17: 16072 | C17: 34943 | D17: 72.00543 | E17: =+'USD PP 1994'!C1004 -> 96.597633 | F17: =+E17/D17 -> 1.3415326 | G17: 36.000283 | I17: 15.67523 | K17: 71.314682
A18: 16103 | C18: 34973 | D18: 71.00427 | E18: =+'USD PP 1994'!C1005 -> 96.301775 | F18: =+E18/D18 -> 1.3562815 | G18: 28.40035 | I18: 14.083765 | K18: 70.274617
A19: 16132 | C19: 35004 | D19: 69.975628 | E19: =+'USD PP 1994'!C1006 -> 96.301775 | F19: =+E19/D19 -> 1.3762188 | G19: 25.998123 | I19: 12.308831 | K19: 69.461913
A20: 16163 | C20: 35034 | D20: 68.900776 | E20: =+'USD PP 1994'!C1007 -> 96.301775 | F20: =+E20/D20 -> 1.3976878 | G20: 24.890496 | I20: 10.591886 | K20: 68.631472
A21: 16193 | C21: 35065 | D21: 67.989714 | E21: =+'USD PP 1994'!C1008 -> 95.857988 | F21: =+E21/D21 -> 1.4098896 | G21: 23.320993 | I21: 8.4620008 | K21: 67.404707
A22: 16224 | C22: 35096 | D22: 67.296559 | E22: =+'USD PP 1994'!C1009 -> 95.414201 | F22: =+E22/D22 -> 1.4178169 | G22: 21.168188 | I22: 6.7485452 | K22: 67.136162
A23: 16254 | C23: 35125 | D23: 67.061843 | E23: =+'USD PP 1994'!C1010 -> 94.970414 | F23: =+E23/D23 -> 1.4161617 | G23: 18.666833 | I23: 5.475493 | K23: 66.982103
A24: 16285 | C24: 35156 | D24: 66.227378 | E24: =+'USD PP 1994'!C1011 -> 94.674556 | F24: =+E24/D24 -> 1.429538 | G24: 16.103203 | I24: 4.3494265 | K24: 65.914292
A25: 16316 | C25: 35186 | D25: 65.429142 | E25: =+'USD PP 1994'!C1012 -> 94.526627 | F25: =+E25/D25 -> 1.4447175 | G25: 14.03941 | I25: 3.5777137 | K25: 65.042719
A26: 16346 | C26: 35217 | D26: 64.659692 | E26: =+'USD PP 1994'!C1013 -> 94.378698 | F26: =+E26/D26 -> 1.4596218 | G26: 12.382616 | I26: 2.9388152 | K26: 64.138368
A27: 16377 | C27: 35247 | D27: 63.949849 | E27: =+'USD PP 1994'!C1014 -> 94.230769 | F27: =+E27/D27 -> 1.4735104 | G27: 10.436254 | I27: 2.394537 | K27: 63.30902
A28: 16407 | C28: 35278 | D28: 63.669702 | E28: =+'USD PP 1994'!C1015 -> 94.08284 | F28: =+E28/D28 -> 1.4776705 | G28: 8.6129027 | I28: 1.9542455 | K28: 63.094499
... A37: 16681 | C37: 35551 | D37: 60.744219 | E37: =+'USD PP 1994'!C1024 -> 92.455621 | F37: =+E37/D37 -> 1.5220481 | G37: 1.238539 | I37: 0.27939501 | K37: 60.750207
A38: 16711 | C38: 35582 | D38: 60.417962 | E38: =+'USD PP 1994'!C1025 -> 92.307692 | F38: =+E38/D38 -> 1.5278187 | I38: 0.22323027 | K38: 59.899632
A39: 16742 | C39: 35612 | D39: 60.285335 | E39: =+'USD PP 1994'!C1026 -> 92.159763 | F39: =+E39/D39 -> 1.5287261 | I39: 0.1733962 | K39: 59.833815
A40: 16772 | C40: 35643 | D40: 60.297394 | E40: =+'USD PP 1994'!C1027 -> 92.011834 | F40: =+E40/D40 -> 1.525967 | I40: 0.13426994 | K40: 60.292035
A41: 16803 | C41: 35674 | D41: 60.261237 | E41: =+'USD PP 1994'!C1028 -> 91.715976 | F41: =+E41/D41 -> 1.521973 | I41: 0.1028652 | K41: 60.286006
A42: 16834 | C42: 35704 | D42: 60.122955 | E42: =+'USD PP 1994'!C1029 -> 91.568047 | F42: =+E42/D42 -> 1.5230131 | I42: 0.078589041 | K42: 60.153668
A43: 16862 | C43: 35735 | D43: 60.020919 | E43: =+'USD PP 1994'!C1030 -> 91.568047 | F43: =+E43/D43 -> 1.5256022 | I43: 0.058661671 | K43: 59.836534
A44: 16893 | C44: 35765 | D44: 59.763934 | E44: =+'USD PP 1994'!C1031 -> 91.715976 | F44: =+E44/D44 -> 1.5346375 | K44: 59.497399
A45: 16923 | C45: 35796 | D45: 59.342602 | E45: =+'USD PP 1994'!C1032 -> 91.568047 | F45: =+E45/D45 -> 1.5430407 | K45: 59.354947
A46: 16954 | C46: 35827 | D46: 59.070876 | E46: =+'USD PP 1994'!C1033 -> 91.420118 | F46: =+E46/D46 -> 1.5476344 | K46: 59.450067
A47: 16984 | C47: 35855 | D47: 58.870715 | E47: =+'USD PP 1994'!C1034 -> 91.272189 | F47: =+E47/D47 -> 1.5503836 | K47: 59.587118
A48: 17015 | C48: 35886 | D48: 58.729764 | E48: =+'USD PP 1994'!C1035 -> 90.976331 | F48: =+E48/D48 -> 1.5490669 | K48: 59.219954
...

Sheet BRL e USD Chart 99
A1: Data | C1: Mês | D1: Real (mar/99 a set/24) | E1: Dólar (mar/99 a set/24) | F1: Câmbio pela PPC | G1: Cruzado (fev-86 a jan-89) | H1: Cruzado Novo (jan-89 a mar-90) | I1: Cruzeiro (mar-90 a ago/93) | J1: Cruzeiro real (ago/93 a jun-94) | K1: Real (jul/94 a jun-21)
A2: 15615 | C2: 34486 | D2: 100 | E2: =+'USD PP 1994'!C989 -> 100 | F2: =+E2/D2 -> 1 | G2: 100 | H2: 100 | I2: 100 | J2: 100 | K2: 100
A3: 15646 | C3: 34516 | D3: 93.597903 | E3: =+'USD PP 1994'!C990 -> 99.704142 | F3: =+E3/D3 -> 1.0652391 | G3: 98.202887 | H3: 87.711604 | I3: 83.201597 | J3: 74.560095 | K3: 93.501636 | P3: =5.2/4.9-1 -> 0.06122449
A4: 15676 | C4: 34547 | D4: 91.888772 | E4: =+'USD PP 1994'!C991 -> 99.260355 | F4: =+E4/D4 -> 1.0802229 | G4: 95.985619 | H4: 82.389258 | I4: 76.662303 | J4: 55.135765 | K4: 91.713228
A5: 15707 | C5: 34578 | D5: 90.50406 | E5: =+'USD PP 1994'!C992 -> 98.964497 | F5: =+E5/D5 -> 1.0934813 | G5: 94.177413 | H5: 74.88571 | I5: 68.632321 | J5: 40.588755 | K5: 90.967296
A6: 15738 | C6: 34608 | D6: 88.193393 | E6: =+'USD PP 1994'!C993 -> 98.964497 | F6: =+E6/D6 -> 1.1221305 | G6: 93.281907 | H6: 64.22996 | I6: 61.65872 | J6: 29.301729 | K6: 88.172237
A7: 15766 | C7: 34639 | D7: 85.782894 | E7: =+'USD PP 1994'!C994 -> 98.816568 | F7: =+E7/D7 -> 1.1519379 | G7: 92.294357 | H7: 51.265033 | I7: 55.136117 | J7: 20.885053 | K7: 85.587494
A8: 15797 | C8: 34669 | D8: 84.340668 | E8: =+'USD PP 1994'!C995 -> 98.816568 | F8: =+E8/D8 -> 1.1716361 | G8: 90.591242 | H8: 40.032042 | I8: 48.736955 | J8: 15.113288 | K8: 84.530859
A9: 15827 | C9: 34700 | D9: 82.930844 | E9: =+'USD PP 1994'!C996 -> 98.372781 | F9: =+E9/D9 -> 1.1862026 | G9: 89.314051 | H9: 30.570479 | I9: 42.07628 | J9: 10.64766 | K9: 83.859979
A10: 15858 | C10: 34731 | D10: 82.093491 | E10: =+'USD PP 1994'!C997 -> 98.076923 | F10: =+E10/D10 -> 1.1946979 | G10: 86.645373 | H10: 22.506426 | I10: 35.48944 | J10: 7.2819448 | K10: 82.767448
A11: 15888 | C11: 34759 | D11: 80.840463 | E11: =+'USD PP 1994'!C998 -> 97.633136 | F11: =+E11/D11 -> 1.2077261 | G11: 82.969811 | H11: 16.393347 | I11: 30.586435 | J11: 5.0185698 | K11: 81.20825
A12: 15919 | C12: 34790 | D12: 78.922643 | E12: =+'USD PP 1994'!C999 -> 97.337278 | F12: =+E12/D12 -> 1.2333251 | G12: 75.22195 | H12: 11.467087 | I12: 25.273868 | J12: 3.3290679 | K12: 79.119495
A13: 15950 | C13: 34820 | D13: 76.870209 | E13: =+'USD PP 1994'!C1000 -> 97.189349 | F13: =+E13/D13 -> 1.2643305 | G13: 66.129187 | H13: 7.5530804 | I13: 20.967204 | K13: 77.590954
A14: 15980 | C14: 34851 | D14: 75.171336 | E14: =+'USD PP 1994'!C1001 -> 97.04142 | F14: =+E14/D14 -> 1.2909365 | G14: 59.425941 | H14: 4.3276688 | I14: 19.508005 | K14: 75.580512
A15: 16011 | C15: 34881 | D15: 73.438195 | E15: =+'USD PP 1994'!C1002 -> 97.04142 | F15: =+E15/D15 -> 1.3214026 | G15: 53.073092 | H15: 2.5432939 | I15: 18.199464 | K15: 72.869757
A16: 16041 | C16: 34912 | D16: 72.718284 | E16: =+'USD PP 1994'!C1003 -> 96.745562 | F16: =+E16/D16 -> 1.3304159 | G16: 45.536758 | H16: 1.419962 | I16: 17.208267 | K16: 71.84241
A17: 16072 | C17: 34943 | D17: 72.00543 | E17: =+'USD PP 1994'!C1004 -> 96.597633 | F17: =+E17/D17 -> 1.3415326 | G17: 36.000283 | I17: 15.67523 | K17: 71.314682
A18: 16103 | C18: 34973 | D18: 71.00427 | E18: =+'USD PP 1994'!C1005 -> 96.301775 | F18: =+E18/D18 -> 1.3562815 | G18: 28.40035 | I18: 14.083765 | K18: 70.274617
A19: 16132 | C19: 35004 | D19: 69.975628 | E19: =+'USD PP 1994'!C1006 -> 96.301775 | F19: =+E19/D19 -> 1.3762188 | G19: 25.998123 | I19: 12.308831 | K19: 69.461913
A20: 16163 | C20: 35034 | D20: 68.900776 | E20: =+'USD PP 1994'!C1007 -> 96.301775 | F20: =+E20/D20 -> 1.3976878 | G20: 24.890496 | I20: 10.591886 | K20: 68.631472
A21: 16193 | C21: 35065 | D21: 67.989714 | E21: =+'USD PP 1994'!C1008 -> 95.857988 | F21: =+E21/D21 -> 1.4098896 | G21: 23.320993 | I21: 8.4620008 | K21: 67.404707
A22: 16224 | C22: 35096 | D22: 67.296559 | E22: =+'USD PP 1994'!C1009 -> 95.414201 | F22: =+E22/D22 -> 1.4178169 | G22: 21.168188 | I22: 6.7485452 | K22: 67.136162
A23: 16254 | C23: 35125 | D23: 67.061843 | E23: =+'USD PP 1994'!C1010 -> 94.970414 | F23: =+E23/D23 -> 1.4161617 | G23: 18.666833 | I23: 5.475493 | K23: 66.982103
A24: 16285 | C24: 35156 | D24: 66.227378 | E24: =+'USD PP 1994'!C1011 -> 94.674556 | F24: =+E24/D24 -> 1.429538 | G24: 16.103203 | I24: 4.3494265 | K24: 65.914292
A25: 16316 | C25: 35186 | D25: 65.429142 | E25: =+'USD PP 1994'!C1012 -> 94.526627 | F25: =+E25/D25 -> 1.4447175 | G25: 14.03941 | I25: 3.5777137 | K25: 65.042719
A26: 16346 | C26: 35217 | D26: 64.659692 | E26: =+'USD PP 1994'!C1013 -> 94.378698 | F26: =+E26/D26 -> 1.4596218 | G26: 12.382616 | I26: 2.9388152 | K26: 64.138368
A27: 16377 | C27: 35247 | D27: 63.949849 | E27: =+'USD PP 1994'!C1014 -> 94.230769 | F27: =+E27/D27 -> 1.4735104 | G27: 10.436254 | I27: 2.394537 | K27: 63.30902
A28: 16407 | C28: 35278 | D28: 63.669702 | E28: =+'USD PP 1994'!C1015 -> 94.08284 | F28: =+E28/D28 -> 1.4776705 | G28: 8.6129027 | I28: 1.9542455 | K28: 63.094499
... A36: 16650 | C36: 35521 | D36: 60.993271 | E36: =+'USD PP 1994'!C1023 -> 92.307692 | F36: =+E36/D36 -> 1.5134078 | G36: 1.6238485 | I36: 0.34952315 | K36: 61.084333
A37: 16681 | C37: 35551 | D37: 60.744219 | E37: =+'USD PP 1994'!C1024 -> 92.455621 | F37: =+E37/D37 -> 1.5220481 | G37: =+USDBRL!D534/'BRL e USD Chart 99'!F37*100 -> 70.162042 | I37: 0.27939501 | K37: 60.750207
A38: 16711 | C38: 35582 | D38: 60.417962 | E38: =+'USD PP 1994'!C1025 -> 92.307692 | F38: =+E38/D38 -> 1.5278187 | G38: =+USDBRL!D535/'BRL e USD Chart 99'!F38*100 -> 70.30939 | I38: 0.22323027 | K38: 59.899632
A39: 16742 | C39: 35612 | D39: 60.285335 | E39: =+'USD PP 1994'!C1026 -> 92.159763 | F39: =+E39/D39 -> 1.5287261 | G39: =+USDBRL!D536/'BRL e USD Chart 99'!F39*100 -> 70.666682 | I39: 0.1733962 | K39: 59.833815
A40: 16772 | C40: 35643 | D40: 60.297394 | E40: =+'USD PP 1994'!C1027 -> 92.011834 | F40: =+E40/D40 -> 1.525967 | G40: =+USDBRL!D537/'BRL e USD Chart 99'!F40*100 -> 71.266285 | I40: 0.13426994 | K40: 60.292035
A41: 16803 | C41: 35674 | D41: 60.261237 | E41: =+'USD PP 1994'!C1028 -> 91.715976 | F41: =+E41/D41 -> 1.521973 | G41: =+USDBRL!D538/'BRL e USD Chart 99'!F41*100 -> 71.827818 | I41: 0.1028652 | K41: 60.286006
A42: 16834 | C42: 35704 | D42: 60.122955 | E42: =+'USD PP 1994'!C1029 -> 91.568047 | F42: =+E42/D42 -> 1.5230131 | G42: =+USDBRL!D539/'BRL e USD Chart 99'!F42*100 -> 72.205551 | I42: 0.078589041 | K42: 60.153668
A43: 16862 | C43: 35735 | D43: 60.020919 | E43: =+'USD PP 1994'!C1030 -> 91.568047 | F43: =+E43/D43 -> 1.5256022 | G43: =+USDBRL!D540/'BRL e USD Chart 99'!F43*100 -> 72.554955 | I43: 0.058661671 | K43: 59.836534
A44: 16893 | C44: 35765 | D44: 59.763934 | E44: =+'USD PP 1994'!C1031 -> 91.715976 | F44: =+E44/D44 -> 1.5346375 | G44: =+USDBRL!D541/'BRL e USD Chart 99'!F44*100 -> 72.538301 | K44: 59.497399
A45: 16923 | C45: 35796 | D45: 59.342602 | E45: =+'USD PP 1994'!C1032 -> 91.568047 | F45: =+E45/D45 -> 1.5430407 | G45: =+USDBRL!D542/'BRL e USD Chart 99'!F45*100 -> 72.551555 | K45: 59.354947
A46: 16954 | C46: 35827 | D46: 59.070876 | E46: =+'USD PP 1994'!C1033 -> 91.420118 | F46: =+E46/D46 -> 1.5476344 | G46: =+USDBRL!D543/'BRL e USD Chart 99'!F46*100 -> 72.801432 | K46: 59.450067
A47: 16984 | C47: 35855 | D47: 58.870715 | E47: =+'USD PP 1994'!C1034 -> 91.272189 | F47: =+E47/D47 -> 1.5503836 | G47: =+USDBRL!D544/'BRL e USD Chart 99'!F47*100 -> 73.09804 | K47: 59.587118
...

Sheet IPCA Chart
A1: Data | B1: IPCA Anual | C1: IPCA Anual | D1: 1
A2: 34516 | D2: =+D1*(1+B2) -> 1
A3: 34547 | D3: =+D2*(1+B3) -> 1
A4: 34578 | D4: =+D3*(1+B4) -> 1
A5: 34608 | D5: =+D4*(1+B5) -> 1
A6: 34639 | D6: =+D5*(1+B6) -> 1
A7: 34669 | D7: =+D6*(1+B7) -> 1
A8: 34700 | D8: =+D7*(1+B8) -> 1
A9: 34731 | D9: =+D8*(1+B9) -> 1
A10: 34759 | D10: =+D9*(1+B10) -> 1
A11: 34790 | D11: =+D10*(1+B11) -> 1
A12: 34820 | D12: =+D11*(1+B12) -> 1
A13: 34851 | B13: 0.3302943 | C13: 0.3302943 | D13: =+D12*(1+B13) -> 1.3302943
A14: 34881 | B14: 0.27451258 | C14: 0.27451258 | D14: =+D13*(1+B14) -> 1.6954768
A15: 34912 | B15: 0.2636268 | C15: 0.2636268 | D15: =+D14*(1+B15) -> 2.1424499
A16: 34943 | B16: 0.25690604 | C16: 0.25690604 | D16: =+D15*(1+B16) -> 2.6928583
A17: 34973 | B17: 0.24208577 | C17: 0.24208577 | D17: =+D16*(1+B17) -> 3.3447609
A18: 35004 | B18: 0.22589673 | C18: 0.22589673 | D18: =+D17*(1+B18) -> 4.1003315
A19: 35034 | B19: 0.2240888 | C19: 0.2240888 | D19: =+D18*(1+B19) -> 5.0191699
A20: 35065 | B20: 0.21975574 | C20: 0.21975574 | D20: =+D19*(1+B20) -> 6.1221613
A21: 35096 | B21: 0.21987649 | C21: 0.21987649 | D21: =+D20*(1+B21) -> 7.4682806
A22: 35125 | B22: 0.2054614 | C22: 0.2054614 | D22: =+D21*(1+B22) -> 9.002724
A23: 35156 | B23: 0.1916921 | C23: 0.1916921 | D23: =+D22*(1+B23) -> 10.728475
A24: 35186 | B24: 0.17486193 | C24: 0.17486193 | D24: =+D23*(1+B24) -> 12.604477
... A358: 45352 | B358: 0.039255961 | C358: 0.039255961 | D358: =+D357*(1+B358) -> 9.1097917e+09

Sheet BRL e USD
A1: Data | C1: Mês | D1: Real (jul/94 a mai-21) | E1: Dólar (jul/94 a mai-21) | F1: Cruzeiro (mai-70 a fev-86) | G1: Cruzado (fev-86 a jan-89) | H1: Cruzado Novo (jan-89 a mar-90) | I1: Cruzeiro (mar-90 a ago/93) | J1: Cruzeiro real (ago/93 a jun-94) | K1: Real (jul/94 a jun-21)
A2: 15615 | C2: 0 | D2: 100 | E2: =+'USD PP 1994'!C989 -> 100 | F2: 100 | G2: 100 | H2: 100 | I2: 100 | J2: 100 | K2: 100
A3: 15646 | C3: 1 | D3: 93.501636 | E3: =+'USD PP 1994'!C990 -> 99.704142 | F3: 98.512462 | G3: 98.202887 | H3: 87.711604 | I3: 83.201597 | J3: 74.560095 | K3: 93.501636
A4: 15676 | C4: 2 | D4: 91.713228 | E4: =+'USD PP 1994'!C991 -> 99.260355 | F4: 97.740313 | G4: 95.985619 | H4: 82.389258 | I4: 76.662303 | J4: 55.135765 | K4: 91.713228
A5: 15707 | C5: 3 | D5: 90.967296 | E5: =+'USD PP 1994'!C992 -> 98.964497 | F5: 96.220037 | G5: 94.177413 | H5: 74.88571 | I5: 68.632321 | J5: 40.588755 | K5: 90.967296
A6: 15738 | C6: 4 | D6: 88.172237 | E6: =+'USD PP 1994'!C993 -> 98.964497 | F6: 93.946531 | G6: 93.281907 | H6: 64.22996 | I6: 61.65872 | J6: 29.301729 | K6: 88.172237
A7: 15766 | C7: 5 | D7: 85.587494 | E7: =+'USD PP 1994'!C994 -> 98.816568 | F7: 92.878429 | G7: 92.294357 | H7: 51.265033 | I7: 55.136117 | J7: 20.885053 | K7: 85.587494
A8: 15797 | C8: 6 | D8: 84.530859 | E8: =+'USD PP 1994'!C995 -> 98.816568 | F8: 91.995274 | G8: 90.591242 | H8: 40.032042 | I8: 48.736955 | J8: 15.113288 | K8: 84.530859
A9: 15827 | C9: 7 | D9: 83.859979 | E9: =+'USD PP 1994'!C996 -> 98.372781 | F9: 90.617882 | G9: 89.314051 | H9: 30.570479 | I9: 42.07628 | J9: 10.64766 | K9: 83.859979
A10: 15858 | C10: 8 | D10: 82.767448 | E10: =+'USD PP 1994'!C997 -> 98.076923 | F10: 88.684559 | G10: 86.645373 | H10: 22.506426 | I10: 35.48944 | J10: 7.2819448 | K10: 82.767448
A11: 15888 | C11: 9 | D11: 81.20825 | E11: =+'USD PP 1994'!C998 -> 97.633136 | F11: 87.073696 | G11: 82.969811 | H11: 16.393347 | I11: 30.586435 | J11: 5.0185698 | K11: 81.20825
A12: 15919 | C12: 10 | D12: 79.119495 | E12: =+'USD PP 1994'!C999 -> 97.337278 | F12: 84.619724 | G12: 75.22195 | H12: 11.467087 | I12: 25.273868 | J12: 3.3290679 | K12: 79.119495
A13: 15950 | C13: 11 | D13: 77.590954 | E13: =+'USD PP 1994'!C1000 -> 97.189349 | F13: 83.509053 | G13: 66.129187 | H13: 7.5530804 | I13: 20.967204 | K13: 77.590954
A14: 15980 | C14: 12 | D14: 75.580512 | E14: =+'USD PP 1994'!C1001 -> 97.04142 | F14: 82.080846 | G14: 59.425941 | H14: 4.3276688 | I14: 19.508005 | K14: 75.580512
A15: 16011 | C15: 13 | D15: 72.869757 | E15: =+'USD PP 1994'!C1002 -> 97.04142 | F15: 80.46353 | G15: 53.073092 | H15: 2.5432939 | I15: 18.199464 | K15: 72.869757
A16: 16041 | C16: 14 | D16: 71.84241 | E16: =+'USD PP 1994'!C1003 -> 96.745562 | F16: 79.407411 | G16: 45.536758 | H16: 1.419962 | I16: 17.208267 | K16: 71.84241
A17: 16072 | C17: 15 | D17: 71.314682 | E17: =+'USD PP 1994'!C1004 -> 96.597633 | F17: 78.303334 | G17: 36.000283 | I17: 15.67523 | K17: 71.314682
A18: 16103 | C18: 16 | D18: 70.274617 | E18: =+'USD PP 1994'!C1005 -> 96.301775 | F18: 77.705005 | G18: 28.40035 | I18: 14.083765 | K18: 70.274617
A19: 16132 | C19: 17 | D19: 69.461913 | E19: =+'USD PP 1994'!C1006 -> 96.301775 | F19: 76.79119 | G19: 25.998123 | I19: 12.308831 | K19: 69.461913
A20: 16163 | C20: 18 | D20: 68.631472 | E20: =+'USD PP 1994'!C1007 -> 96.301775 | F20: 75.8132 | G20: 24.890496 | I20: 10.591886 | K20: 68.631472
A21: 16193 | C21: 19 | D21: 67.404707 | E21: =+'USD PP 1994'!C1008 -> 95.857988 | F21: 75.136967 | G21: 23.320993 | I21: 8.4620008 | K21: 67.404707
A22: 16224 | C22: 20 | D22: 67.136162 | E22: =+'USD PP 1994'!C1009 -> 95.414201 | F22: 73.490774 | G22: 21.168188 | I22: 6.7485452 | K22: 67.136162
A23: 16254 | C23: 21 | D23: 66.982103 | E23: =+'USD PP 1994'!C1010 -> 94.970414 | F23: 72.468962 | G23: 18.666833 | I23: 5.475493 | K23: 66.982103
A24: 16285 | C24: 22 | D24: 65.914292 | E24: =+'USD PP 1994'!C1011 -> 94.674556 | F24: 71.751447 | G24: 16.103203 | I24: 4.3494265 | K24: 65.914292
A25: 16316 | C25: 23 | D25: 65.042719 | E25: =+'USD PP 1994'!C1012 -> 94.526627 | F25: 70.88663 | G25: 14.03941 | I25: 3.5777137 | K25: 65.042719
A26: 16346 | C26: 24 | D26: 64.138368 | E26: =+'USD PP 1994'!C1013 -> 94.378698 | F26: 70.421846 | G26: 12.382616 | I26: 2.9388152 | K26: 64.138368
A27: 16377 | C27: 25 | D27: 63.30902 | E27: =+'USD PP 1994'!C1014 -> 94.230769 | F27: 69.641857 | G27: 10.436254 | I27: 2.394537 | K27: 63.30902
A28: 16407 | C28: 26 | D28: 63.094499 | E28: =+'USD PP 1994'!C1015 -> 94.08284 | F28: 68.0628 | G28: 8.6129027 | I28: 1.9542455 | K28: 63.094499
... A37: 16681 | C37: 35 | D37: 60.750207 | E37: =+'USD PP 1994'!C1024 -> 92.455621 | F37: 60.509572 | G37: 1.238539 | I37: 0.27939501 | K37: 60.750207
A38: 16711 | C38: 36 | D38: 59.899632 | E38: =+'USD PP 1994'!C1025 -> 92.307692 | F38: 60.023382 | I38: 0.22323027 | K38: 59.899632
A39: 16742 | C39: 37 | D39: 59.833815 | E39: =+'USD PP 1994'!C1026 -> 92.159763 | F39: 59.558824 | I39: 0.1733962 | K39: 59.833815
A40: 16772 | C40: 38 | D40: 60.292035 | E40: =+'USD PP 1994'!C1027 -> 92.011834 | F40: 58.922461 | I40: 0.13426994 | K40: 60.292035
A41: 16803 | C41: 39 | D41: 60.286006 | E41: =+'USD PP 1994'!C1028 -> 91.715976 | F41: 58.298665 | I41: 0.1028652 | K41: 60.286006
A42: 16834 | C42: 40 | D42: 60.153668 | E42: =+'USD PP 1994'!C1029 -> 91.568047 | F42: 57.584616 | I42: 0.078589041 | K42: 60.153668
A43: 16862 | C43: 41 | D43: 59.836534 | E43: =+'USD PP 1994'!C1030 -> 91.568047 | F43: 56.946812 | I43: 0.058661671 | K43: 59.836534
A44: 16893 | C44: 42 | D44: 59.497399 | E44: =+'USD PP 1994'!C1031 -> 91.715976 | F44: 56.422086 | K44: 59.497399
A45: 16923 | C45: 43 | D45: 59.354947 | E45: =+'USD PP 1994'!C1032 -> 91.568047 | F45: 56.130209 | K45: 59.354947
A46: 16954 | C46: 44 | D46: 59.450067 | E46: =+'USD PP 1994'!C1033 -> 91.420118 | F46: 55.607499 | K46: 59.450067
A47: 16984 | C47: 45 | D47: 59.587118 | E47: =+'USD PP 1994'!C1034 -> 91.272189 | F47: 53.695924 | K47: 59.587118
A48: 17015 | C48: 46 | D48: 59.219954 | E48: =+'USD PP 1994'!C1035 -> 90.976331 | F48: 51.551386 | K48: 59.219954
...

Sheet BD
A1: Data | B1: 193 - Índice de preços ao consumidor-São Paulo (IPC-Fipe) - Var. % mensal | C1: 433 - Índice nacional de preços ao consumidor-amplo (IPCA) - Var. % mensal | D1: 1788 - BM - Base monetária restrita (saldo em final de período) - u.m.c. (mil) | E1: 1827 - Meios de pagamento - M1 (saldo em final de período) - u.m.c. (mil) | F1: 1837 - Meios de pagamento amplos - M2 (saldo em final de período) - u.m.c. (mil) | M1: 433 - Índice nacional de preços ao consumidor-amplo (IPCA) - Var. % mensal
A2: 14277 | B2: -1.52 | C2: - | D2: - | E2: - | F2: - | M2: -
A3: 14305 | B3: 2.48 | C3: - | D3: - | E3: - | F3: - | M3: -
A4: 14336 | B4: 1.81 | C4: - | D4: - | E4: - | F4: - | M4: -
A5: 14366 | B5: 0 | C5: - | D5: - | E5: - | F5: - | M5: -
A6: 14397 | B6: -0.3 | C6: - | D6: - | E6: - | F6: - | M6: -
A7: 14427 | B7: -0.89 | C7: - | D7: - | E7: - | F7: - | M7: -
A8: 14458 | B8: 0.7 | C8: - | D8: - | E8: - | F8: - | M8: -
A9: 14489 | B9: -0.99 | C9: - | D9: - | E9: - | F9: - | M9: -
A10: 14519 | B10: 1.31 | C10: - | D10: - | E10: - | F10: - | M10: -
A11: 14550 | B11: 0.3 | C11: - | D11: - | E11: - | F11: - | M11: -
A12: 14580 | B12: -1.38 | C12: - | D12: - | E12: - | F12: - | M12: -
A13: 14611 | B13: 4.81 | C13: - | D13: - | E13: - | F13: - | M13: -
... A84: 16772 | B84: -0.08 | C84: - | D84: - | E84: - | F84: - | M84: -
A85: 16803 | B85: -3.14 | C85: - | D85: 22900000 | E85: 39600000 | F85: - | M85: -
A86: 16834 | B86: 2.11 | C86: - | D86: 23600000 | E86: 39300000 | F86: - | M86: -
A87: 16862 | B87: 8.29 | C87: - | D87: 23900000 | E87: 38600000 | F87: - | M87: -
A88: 16893 | B88: 1.34 | C88: - | D88: 23700000 | E88: 42000000 | F88: - | M88: -
A89: 16923 | B89: 1.6 | C89: - | D89: 24200000 | E89: 42700000 | F89: - | M89: -
A90: 16954 | B90: 1.99 | C90: - | D90: 24900000 | E90: 43400000 | F90: - | M90: -
A91: 16984 | B91: 3.36 | C91: - | D91: 25500000 | E91: 43800000 | F91: - | M91: -
A92: 17015 | B92: 2.86 | C92: - | D92: 25700000 | E92: 44900000 | F92: - | M92: -
A93: 17046 | B93: -2.46 | C93: - | D93: 25700000 | E93: 45300000 | F93: - | M93: -
A94: 17076 | B94: 1.04 | C94: - | D94: 25600000 | E94: 45400000 | F94: - | M94: -
A95: 17107 | B95: 1.28 | C95: - | D95: 25300000 | E95: 45800000 | F95: - | M95: -
A96: 17137 | B96: -0.32 | C96: - | D96: 25700000 | E96: 45400000 | F96: - | M96: -
... A492: 29190 | B492: 7.06 | C492: - | D492: 366247000 | E492: 838226000 | F492: - | M492: -
A493: 29221 | B493: 4.48 | C493: 6.62 | D493: 339824000 | E493: 814000000 | F493: - | M493: 0.0662
A494: 29252 | B494: 3.35 | C494: 4.62 | D494: 323939000 | E494: 845000000 | F494: - | M494: 0.0462
A495: 29281 | B495: 4.34 | C495: 6.04 | D495: 337933000 | E495: 878000000 | F495: - | M495: 0.0604
A496: 29312 | B496: 3.93 | C496: 5.29 | D496: 364959000 | E496: 957000000 | F496: - | M496: 0.0529
A497: 29342 | B497: 6.52 | C497: 5.7 | D497: 372738000 | E497: 1011000000 | F497: - | M497: 0.057
A498: 29373 | B498: 5.02 | C498: 5.31 | D498: 416236000 | E498: 1101000000 | F498: - | M498: 0.0531
A499: 29403 | B499: 5.24 | C499: 5.55 | D499: 439890000 | E499: 1076000000 | F499: - | M499: 0.0555
A500: 29434 | B500: 5.46 | C500: 4.95 | D500: 446615000 | E500: 1129000000 | F500: - | M500: 0.0495
A501: 29465 | B501: 6.15 | C501: 4.23 | D501: 459175000 | E501: 1170000000 | F501: - | M501: 0.0423
A502: 29495 | B502: 6.78 | C502: 9.48 | D502: 468517000 | E502: 1221000000 | F502: - | M502: 0.0948
A503: 29526 | B503: 6.82 | C503: 6.67 | D503: 512562000 | E503: 1326000000 | F503: - | M503: 0.0667
A504: 29556 | B504: 4.97 | C504: 6.61 | D504: 580353000 | E504: 1487000000 | F504: - | M504: 0.0661
... A594: 32295 | B594: 21.7 | C594: 22 | D594: 911031000 | E594: 1844000000 | F594: - | M594: 0.22
...

Sheet Moedas
A1: Data | B1: 193 - Índice de preços ao consumidor-São Paulo (IPC-Fipe) - Var. % mensal | C1: Cruzeiro (nov/42 a fev/67 | D1: Cruzeiro Novo (fev-67 a mai-70) | E1: Cruzeiro (mai-70 a fev-86) | F1: Cruzado (fev-86 a jan-89) | G1: Cruzado Novo (jan-89 a mar-90) | H1: Cruzeiro (mar-90 a ago/93) | I1: Cruzeiro real (ago/93 a jun-94) | J1: Real (jul/94 a jun-21) | K1: 433 - Índice nacional de preços ao consumidor-amplo (IPCA) - Var. % mensal | L1: 1788 - BM - Base monetária restrita (saldo em final de período) - u.m.c. (mil) | M1: 1827 - Meios de pagamento - M1 (saldo em final de período) - u.m.c. (mil) | N1: 1837 - Meios de pagamento amplos - M2 (saldo em final de período) - u.m.c. (mil)
A2: 14277 | B2: -1.52 | D2: -1.52 | E2: -1.52 | F2: -1.52 | G2: -1.52 | H2: -1.52 | I2: -1.52 | J2: -1.52 | K2: - | L2: - | M2: - | N2: -
A3: 14305 | B3: 2.48 | D3: 2.48 | E3: 2.48 | F3: 2.48 | G3: 2.48 | H3: 2.48 | I3: 2.48 | J3: 2.48 | K3: - | L3: - | M3: - | N3: -
A4: 14336 | B4: 1.81 | D4: 1.81 | E4: 1.81 | F4: 1.81 | G4: 1.81 | H4: 1.81 | I4: 1.81 | J4: 1.81 | K4: - | L4: - | M4: - | N4: -
A5: 14366 | B5: 0 | D5: 0 | E5: 0 | F5: 0 | G5: 0 | H5: 0 | I5: 0 | J5: 0 | K5: - | L5: - | M5: - | N5: -
A6: 14397 | B6: -0.3 | D6: -0.3 | E6: -0.3 | F6: -0.3 | G6: -0.3 | H6: -0.3 | I6: -0.3 | J6: -0.3 | K6: - | L6: - | M6: - | N6: -
A7: 14427 | B7: -0.89 | D7: -0.89 | E7: -0.89 | F7: -0.89 | G7: -0.89 | H7: -0.89 | I7: -0.89 | J7: -0.89 | K7: - | L7: - | M7: - | N7: -
A8: 14458 | B8: 0.7 | D8: 0.7 | E8: 0.7 | F8: 0.7 | G8: 0.7 | H8: 0.7 | I8: 0.7 | J8: 0.7 | K8: - | L8: - | M8: - | N8: -
A9: 14489 | B9: -0.99 | D9: -0.99 | E9: -0.99 | F9: -0.99 | G9: -0.99 | H9: -0.99 | I9: -0.99 | J9: -0.99 | K9: - | L9: - | M9: - | N9: -
A10: 14519 | B10: 1.31 | D10: 1.31 | E10: 1.31 | F10: 1.31 | G10: 1.31 | H10: 1.31 | I10: 1.31 | J10: 1.31 | K10: - | L10: - | M10: - | N10: -
A11: 14550 | B11: 0.3 | D11: 0.3 | E11: 0.3 | F11: 0.3 | G11: 0.3 | H11: 0.3 | I11: 0.3 | J11: 0.3 | K11: - | L11: - | M11: - | N11: -
A12: 14580 | B12: -1.38 | D12: -1.38 | E12: -1.38 | F12: -1.38 | G12: -1.38 | H12: -1.38 | I12: -1.38 | J12: -1.38 | K12: - | L12: - | M12: - | N12: -
A13: 14611 | B13: 4.81 | D13: 4.81 | E13: 4.81 | F13: 4.81 | G13: 4.81 | H13: 4.81 | I13: 4.81 | J13: 4.81 | K13: - | L13: - | M13: - | N13: -
... A46: 15615 | B46: -1.2 | D46: -1.2 | E46: -1.2 | F46: -1.2 | G46: -1.2 | H46: -1.2 | I46: -1.2 | J46: -1.2 | K46: - | L46: - | M46: - | N46: -
A47: 15646 | B47: 0.28 | C47: 0.28 | D47: 0.28 | E47: 0.28 | F47: 0.28 | G47: 0.28 | H47: 0.28 | I47: 0.28 | J47: 0.28 | K47: - | L47: - | M47: - | N47: -
A48: 15676 | B48: -0.21 | C48: -0.21 | D48: -0.21 | E48: -0.21 | F48: -0.21 | G48: -0.21 | H48: -0.21 | I48: -0.21 | J48: -0.21 | K48: - | L48: - | M48: - | N48: -
A49: 15707 | B49: 1.85 | C49: 1.85 | D49: 1.85 | E49: 1.85 | F49: 1.85 | G49: 1.85 | H49: 1.85 | I49: 1.85 | J49: 1.85 | K49: - | L49: - | M49: - | N49: -
A50: 15738 | B50: 1.4 | C50: 1.4 | D50: 1.4 | E50: 1.4 | F50: 1.4 | G50: 1.4 | H50: 1.4 | I50: 1.4 | J50: 1.4 | K50: - | L50: - | M50: - | N50: -
A51: 15766 | B51: -0.14 | C51: -0.14 | D51: -0.14 | E51: -0.14 | F51: -0.14 | G51: -0.14 | H51: -0.14 | I51: -0.14 | J51: -0.14 | K51: - | L51: - | M51: - | N51: -
A52: 15797 | B52: 3.11 | C52: 3.11 | D52: 3.11 | E52: 3.11 | F52: 3.11 | G52: 3.11 | H52: 3.11 | I52: 3.11 | J52: 3.11 | K52: - | L52: - | M52: - | N52: -
A53: 15827 | B53: 0.4 | C53: 0.4 | D53: 0.4 | E53: 0.4 | F53: 0.4 | G53: 0.4 | H53: 0.4 | I53: 0.4 | J53: 0.4 | K53: - | L53: - | M53: - | N53: -
A54: 15858 | B54: -0.47 | C54: -0.47 | D54: -0.47 | E54: -0.47 | F54: -0.47 | G54: -0.47 | H54: -0.47 | I54: -0.47 | J54: -0.47 | K54: - | L54: - | M54: - | N54: -
A55: 15888 | B55: 3.08 | C55: 3.08 | D55: 3.08 | E55: 3.08 | F55: 3.08 | G55: 3.08 | H55: 3.08 | I55: 3.08 | J55: 3.08 | K55: - | L55: - | M55: - | N55: -
A56: 15919 | B56: 0.19 | C56: 0.19 | D56: 0.19 | E56: 0.19 | F56: 0.19 | G56: 0.19 | H56: 0.19 | I56: 0.19 | J56: 0.19 | K56: - | L56: - | M56: - | N56: -
A57: 15950 | B57: 2.08 | C57: 2.08 | D57: 2.08 | E57: 2.08 | F57: 2.08 | G57: 2.08 | H57: 2.08 | I57: 2.08 | J57: 2.08 | K57: - | L57: - | M57: - | N57: -
A58: 15980 | B58: 4.19 | C58: 4.19 | D58: 4.19 | E58: 4.19 | F58: 4.19 | G58: 4.19 | H58: 4.19 | I58: 4.19 | J58: 4.19 | K58: - | L58: - | M58: - | N58: -
... A84: 16772 | B84: -0.08 | C84: -0.08 | D84: -0.08 | E84: -0.08 | F84: -0.08 | G84: -0.08 | H84: -0.08 | I84: -0.08 | J84: -0.08 | K84: - | L84: - | M84: - | N84: -
A85: 16803 | B85: -3.14 | C85: -3.14 | D85: -3.14 | E85: -3.14 | F85: -3.14 | G85: -3.14 | H85: -3.14 | I85: -3.14 | J85: -3.14 | K85: - | L85: 22900000 | M85: 39600000 | N85: -
A86: 16834 | B86: 2.11 | C86: 2.11 | D86: 2.11 | E86: 2.11 | F86: 2.11 | G86: 2.11 | H86: 2.11 | I86: 2.11 | J86: 2.11 | K86: - | L86: 23600000 | M86: 39300000 | N86: -
A87: 16862 | B87: 8.29 | C87: 8.29 | D87: 8.29 | E87: 8.29 | F87: 8.29 | G87: 8.29 | H87: 8.29 | I87: 8.29 | J87: 8.29 | K87: - | L87: 23900000 | M87: 38600000 | N87: -
A88: 16893 | B88: 1.34 | C88: 1.34 | D88: 1.34 | E88: 1.34 | F88: 1.34 | G88: 1.34 | H88: 1.34 | I88: 1.34 | J88: 1.34 | K88: - | L88: 23700000 | M88: 42000000 | N88: -
A89: 16923 | B89: 1.6 | C89: 1.6 | D89: 1.6 | E89: 1.6 | F89: 1.6 | G89: 1.6 | H89: 1.6 | I89: 1.6 | J89: 1.6 | K89: - | L89: 24200000 | M89: 42700000 | N89: -
A90: 16954 | B90: 1.99 | C90: 1.99 | D90: 1.99 | E90: 1.99 | F90: 1.99 | G90: 1.99 | H90: 1.99 | I90: 1.99 | J90: 1.99 | K90: - | L90: 24900000 | M90: 43400000 | N90: -
A91: 16984 | B91: 3.36 | C91: 3.36 | D91: 3.36 | E91: 3.36 | F91: 3.36 | G91: 3.36 | H91: 3.36 | I91: 3.36 | J91: 3.36 | K91: - | L91: 25500000 | M91: 43800000 | N91: -
A92: 17015 | B92: 2.86 | C92: 2.86 | D92: 2.86 | E92: 2.86 | F92: 2.86 | G92: 2.86 | H92: 2.86 | I92: 2.86 | J92: 2.86 | K92: - | L92: 25700000 | M92: 44900000 | N92: -
A93: 17046 | B93: -2.46 | C93: -2.46 | D93: -2.46 | E93: -2.46 | F93: -2.46 | G93: -2.46 | H93: -2.46 | I93: -2.46 | J93: -2.46 | K93: - | L93: 25700000 | M93: 45300000 | N93: -
A94: 17076 | B94: 1.04 | C94: 1.04 | D94: 1.04 | E94: 1.04 | F94: 1.04 | G94: 1.04 | H94: 1.04 | I94: 1.04 | J94: 1.04 | K94: - | L94: 25600000 | M94: 45400000 | N94: -
A95: 17107 | B95: 1.28 | C95: 1.28 | D95: 1.28 | E95: 1.28 | F95: 1.28 | G95: 1.28 | H95: 1.28 | I95: 1.28 | J95: 1.28 | K95: - | L95: 25300000 | M95: 45800000 | N95: -
A96: 17137 | B96: -0.32 | C96: -0.32 | D96: -0.32 | E96: -0.32 | F96: -0.32 | G96: -0.32 | H96: -0.32 | I96: -0.32 | J96: -0.32 | K96: - | L96: 25700000 | M96: 45400000 | N96: -
... A338: 24504 | B338: 1.52 | C338: 1.52 | D338: 1.52 | E338: 1.52 | F338: 1.52 | G338: 1.52 | H338: 1.52 | I338: 1.52 | J338: 1.52 | K338: - | L338: 4844600 | M338: 10584000 | N338: -
...

Sheet Moedas BD
