Workbook
Name _A1: #REF!
Name a: [1]Gold_Monthly!$K$2
Name Active_dt: #REF!
Name Active_qtr: #REF!
Name Active_yr: #REF!
Name ActiveQtrNo: #REF!
Name ag: #REF!
Name all: #REF!,#REF!,#REF!,#REF!
Name All_Countries: #REF!
Name ANALYSIS_TYPE: #REF!
Name annual: #REF!
Name Argentina: #REF!
Name Armenia: #REF!
Name asd: #REF!
Name Ashish: [2]Gold_Qrtly!$K$2
Name asset1: OFFSET('[3]Charts Avg'!$C$7,,,COUNTIF('[3]Charts Avg'!$C$7:$C$9,"<>"))
Name asset10: OFFSET('[3]Charts Avg'!$L$7,,,COUNTIF('[3]Charts Avg'!$L$7:$L$9,"<>"))
Name asset11: OFFSET('[3]Charts Avg'!$M$7,,,COUNTIF('[3]Charts Avg'!$M$7:$M$9,"<>"))
Name asset12: OFFSET('[3]Charts Avg'!$N$7,,,COUNTIF('[3]Charts Avg'!$N$7:$N$9,"<>"))
Name asset13: OFFSET('[3]Charts Avg'!$O$7,,,COUNTIF('[3]Charts Avg'!$O$7:$O$9,"<>"))
Name asset14: OFFSET('[3]Charts Avg'!$P$7,,,COUNTIF('[3]Charts Avg'!$P$7:$P$9,"<>"))
Name asset15: OFFSET('[3]Charts Avg'!$Q$7,,,COUNTIF('[3]Charts Avg'!$Q$7:$Q$9,"<>"))
Name asset16: OFFSET('[3]Charts Avg'!$R$7,,,COUNTIF('[3]Charts Avg'!$R$7:$R$9,"<>"))
Name asset17: OFFSET('[3]Charts Avg'!$S$7,,,COUNTIF('[3]Charts Avg'!$S$7:$S$9,"<>"))
Name asset18: OFFSET('[3]Charts Avg'!$T$7,,,COUNTIF('[3]Charts Avg'!$T$7:$T$9,"<>"))
Name asset2: OFFSET('[3]Charts Avg'!$D$7,,,COUNTIF('[3]Charts Avg'!$D$7:$D$9,"<>"))
Name asset3: OFFSET('[3]Charts Avg'!$E$7,,,COUNTIF('[3]Charts Avg'!$E$7:$E$9,"<>"))
Name asset4: OFFSET('[3]Charts Avg'!$F$7,,,COUNTIF('[3]Charts Avg'!$F$7:$F$9,"<>"))
Name asset5: OFFSET('[3]Charts Avg'!$G$7,,,COUNTIF('[3]Charts Avg'!$G$7:$G$9,"<>"))
Name asset6: OFFSET('[3]Charts Avg'!$H$7,,,COUNTIF('[3]Charts Avg'!$H$7:$H$9,"<>"))
Name asset7: OFFSET('[3]Charts Avg'!$I$7,,,COUNTIF('[3]Charts Avg'!$I$7:$I$9,"<>"))
Name asset8: OFFSET('[3]Charts Avg'!$J$7,,,COUNTIF('[3]Charts Avg'!$J$7:$J$9,"<>"))
Name asset9: OFFSET('[3]Charts Avg'!$K$7,,,COUNTIF('[3]Charts Avg'!$K$7:$K$9,"<>"))
Name ASSETS: #REF!
Name AUDx: INDIRECT("Daily_Indexed!AB2880:AB"&'Above-ground stocks'!MaxRow,1)
Name AUDx: INDIRECT("Daily_Indexed!AB2880:AB"&'Above-ground stocks'!MaxRow,1)
Name Australia: #REF!
Name AVG_GROWTH_YEARS: #REF!,#REF!,#REF!,#REF!,#REF!,#REF!,#REF!,#REF!,#REF!,#REF!,#REF!,#REF!,#REF!,#REF!,#REF!,#REF!,#REF!,#REF!,#REF!,#REF!,#REF!,#REF!,#REF!,#REF!,#REF!,#REF!,#REF!,#REF!,#REF!
Name Azerbaijan: #REF!
Name BB_ABS_REL: #REF!
Name BB_ADJ_FLAG: #REF!
Name BB_BEST_SOURCE: #REF!
Name BB_CASE_ON_OFF: #REF!
Name BB_CASE_SELECTION: #REF!
Name BB_CASE1: #REF!
Name BB_CASE2: #REF!
Name BB_CASE3: #REF!
Name BB_CRNCY: IF(ISBLANK(#REF!),#REF!,#REF!)
Name BB_DRIVERS_BEG_HIST_DATA: OFFSET(#REF!,0,1)
Name BB_DRIVERS_FY1: #REF!
Name BB_DRIVERS_FY2: #REF!
Name BB_DRIVERS_FY3: #REF!
Name BB_FUND_IND: #REF!
Name BB_FUNDING_GAP_TYPE: #REF!
Name BB_PPE_NET_GROSS: #REF!
Name BB_PRIM_PER: #REF!
Name BB_RI_PV_BASE: #REF!
Name BB_RI_PV_BEAR: #REF!
Name BB_RI_PV_BULL: #REF!
Name BB_RI_TV_BASE: #REF!

Sheet Currency Comp
B1: Dólar americano | C1: Euro | D1: Iene japonês | E1: Libra esterlina | F1: Dólar canadense | G1: Dólar australiano | H1: Yuan chinês | I1: Franco suíco | J1: Outras moedas | K1: Ouro | M1: Preço do Ouro
A2: 1999-Q1 | B2: 882325.11 | C2: 224608.5 | D2: 74773.498 | E2: 34014.702 | I2: 3571.2763 | J2: 20121.333 | M2: 286.76
A3: 1999-Q2 | B3: 918685.13 | C3: 223853.66 | D3: 71673.745 | E3: 35573.742 | I3: 3092.3568 | J3: 20845.13 | M3: 273.01
A4: 1999-Q3 | B4: 936039 | C4: 242702.36 | D4: 82726.03 | E4: 37029.314 | I4: 3193.2782 | J4: 22554.526 | M4: 259.21
A5: 1999-Q4 | B5: 979782.72 | C5: 246950.5 | D5: 87938.695 | E5: 39827.371 | I5: 3171.8646 | J5: 22033.791 | M5: 296.02 | O5: official foreign holdings of treasuries | R5: official foreign holdings of treasuries (% of reserves excluding usa) | S5: gold (% of foreign reserves excluding usa) | U5: United States total | V5: United States gold
A6: 2000-Q1 | B6: 1275674.5 | C6: 297939.52 | D6: 108165.73 | E6: 68573.693 | I6: 5505.958 | J6: 46028.487 | K6: 297573.77 | M6: 290.16 | O6: 633884 | Q6: =A6 -> 2000-Q1 | R6: =O6/(SUM(B6:K6)-U6) -> 0.32220962 | S6: =(K6-V6)/(SUM(B6:K6)-V7) -> 0.11123916 | U6: 132158.52 | V6: 72417.463
A7: 2000-Q2 | B7: 1304391.1 | C7: 309563.57 | D7: 125902.31 | E7: 60518.59 | I7: 3849.3588 | J7: 41376.305 | K7: 308196.14 | M7: 280.32 | O7: 630288 | Q7: =A7 -> 2000-Q2 | R7: =O7/(SUM(B7:K7)-U7) -> 0.31179212 | S7: =(K7-V7)/(SUM(B7:K7)-V8) -> 0.11180852 | U7: 132296.67 | V7: 75387.553
A8: 2000-Q3 | B8: 1320315 | C8: 306925.07 | D8: 131825.07 | E8: 61863.604 | I8: 4262.4165 | J8: 43800.236 | K8: 293061.99 | M8: 276.54 | O8: 619689 | Q8: =A8 -> 2000-Q3 | R8: =O8/(SUM(B8:K8)-U8) -> 0.30447753 | S8: =(K8-V8)/(SUM(B8:K8)-V9) -> 0.10595482 | U8: 126799.74 | V8: 71589.482
A9: 2000-Q4 | B9: 1347789.2 | C9: 338918.13 | D9: 126811.28 | E9: 65957.757 | I9: 5806.1677 | J9: 47299.748 | K9: 293061.6 | M9: 268.96 | O9: 639796 | Q9: =A9 -> 2000-Q4 | R9: =O9/(SUM(B9:K9)-U9) -> 0.30506507 | S9: =(K9-V9)/(SUM(B9:K9)-V10) -> 0.10252056 | U9: 128399.52 | V9: 71799.139
A10: 2001-Q1 | B10: 1366647.1 | C10: 333212.58 | D10: 114931.21 | E10: 65532.539 | I10: 5363.8052 | J10: 48701.335 | K10: 273950.29 | M10: 263.51 | O10: 655812 | Q10: =A10 -> 2001-Q1 | R10: =O10/(SUM(B10:K10)-U10) -> 0.3141246 | S10: =(K10-V10)/(SUM(B10:K10)-V11) -> 0.096620205 | U10: 120594.03 | V10: 67418.701
A11: 2001-Q2 | B11: 1387957.9 | C11: 333446.21 | D11: 112683.35 | E11: 60775.338 | I11: 5292.3576 | J11: 43755.01 | K11: 287330.69 | M11: 267.92 | O11: 636246 | Q11: =A11 -> 2001-Q2 | R11: =O11/(SUM(B11:K11)-U11) -> 0.3020165 | S11: =(K11-V11)/(SUM(B11:K11)-V12) -> 0.10051429 | U11: 124581.1 | V11: 70777.802
A12: 2001-Q3 | B12: 1444045.3 | C12: 366636.56 | D12: 116793.59 | E12: 62633.836 | I12: 5174.5976 | J12: 45384.154 | K12: 310180.77 | M12: 274.17 | O12: 651007 | Q12: =A12 -> 2001-Q3 | R12: =O12/(SUM(B12:K12)-U12) -> 0.29402059 | S12: =(K12-V12)/(SUM(B12:K12)-V13) -> 0.10243503 | U12: 136694.36 | V12: 76792.2
A13: 2001-Q4 | B13: 1458704.2 | C13: 379290.72 | D13: 111184.16 | E13: 64033.904 | I13: 5020.0517 | J13: 42559.092 | K13: 292768.83 | M13: 278.64 | O13: 720149 | Q13: =A13 -> 2001-Q4 | R13: =O13/(SUM(B13:K13)-U13) -> 0.32388311 | S13: =(K13-V13)/(SUM(B13:K13)-V14) -> 0.096863801 | U13: 130076.68 | V13: 72443
A14: 2002-Q1 | B14: 1476475.1 | C14: 398762.15 | D14: 98221.89 | E14: 68925.219 | I14: 6199.5823 | J14: 45297.098 | K14: 317993.54 | M14: 290.07 | O14: 724569 | Q14: =A14 -> 2002-Q1 | R14: =O14/(SUM(B14:K14)-U14) -> 0.31829902 | S14: =(K14-V14)/(SUM(B14:K14)-V15) -> 0.10265586 | U14: 135496.19 | V14: 78966.8
A15: 2002-Q2 | B15: 1525516.7 | C15: 451908.27 | D15: 139764.86 | E15: 73237.281 | I15: 6443.9682 | J15: 52967.083 | K15: 334195.01 | M15: 312.4 | O15: 743943 | Q15: =A15 -> 2002-Q2 | R15: =O15/(SUM(B15:K15)-U15) -> 0.30527828 | S15: =(K15-V15)/(SUM(B15:K15)-V16) -> 0.10033035 | U15: 147099.25 | V15: 83447
A16: 2002-Q3 | B16: 1549158.3 | C16: 491325.62 | D16: 134236.54 | E16: 83328.141 | I16: 7048.9299 | J16: 57699.677 | K16: 338823.02 | M16: 314.2 | O16: 753067 | Q16: =A16 -> 2002-Q3 | R16: =O16/(SUM(B16:K16)-U16) -> 0.29978868 | S16: =(K16-V16)/(SUM(B16:K16)-V17) -> 0.098812844 | U16: 149627.45 | V16: 84809.4
A17: 2002-Q4 | B17: 1572812.6 | C17: 555199.44 | D17: 135716.15 | E17: 88953.597 | I17: 9477.3994 | J17: 59818.502 | K17: 363503.21 | M17: 321.87 | O17: 811995 | Q17: =A17 -> 2002-Q4 | R17: =O17/(SUM(B17:K17)-U17) -> 0.30914863 | S17: =(K17-V17)/(SUM(B17:K17)-V18) -> 0.10101794 | U17: 158928.81 | V17: 90966.4
... A56: 2012-Q3 | B56: 6679225.5 | C56: 2307012.7 | D56: 484243.62 | E56: 518988.72 | I56: 37111.641 | J56: 780355.86 | K56: 1800328.6 | M56: 1652 | O56: 3958112 | Q56: =A56 -> 2012-Q3 | R56: =O56/(SUM(B56:K56)-U56) -> 0.3298204 | S56: =(K56-V56)/(SUM(B56:K56)-V57) -> 0.10973591 | U56: 606456.42 | V56: 464422.09
A57: 2012-Q4 | B57: 6780737.5 | C57: 2351759.6 | D57: 472856.54 | E57: 518126.81 | F57: 229640.57 | G57: 183455.43 | I57: 32981.994 | J57: 394659.5 | K57: 1688712.7 | M57: 1721.79 | O57: 4032835 | Q57: =A57 -> 2012-Q4 | R57: =O57/(SUM(B57:K57)-U57) -> 0.33383394 | S57: =(K57-V57)/(SUM(B57:K57)-V58) -> 0.10259741 | U57: 572568.34 | V57: 433434.47
A58: 2013-Q1 | B58: 6892963.1 | C58: 2334010.3 | D58: 469360.05 | E58: 515044.64 | F58: 243970.27 | G58: 199792.75 | I58: 38345.872 | J58: 409977.11 | K58: 1641405 | M58: 1631.77 | O58: 4093764 | Q58: =A58 -> 2013-Q1 | R58: =O58/(SUM(B58:K58)-U58) -> 0.3357845 | S58: =(K58-V58)/(SUM(B58:K58)-V59) -> 0.09840331 | U58: 553228.29 | V58: 417940.66
A59: 2013-Q2 | B59: 6917483 | C59: 2357139.9 | D59: 478216.68 | E59: 514108.85 | F59: 258107.29 | G59: 201299.83 | I59: 38240.181 | J59: 385883.39 | K59: 1228277.4 | M59: 1414.8 | O59: 4012216 | Q59: =A59 -> 2013-Q2 | R59: =O59/(SUM(B59:K59)-U59) -> 0.33624585 | S59: =(K59-V59)/(SUM(B59:K59)-V60) -> 0.076178522 | U59: 446368.32 | V59: 311706.72
A60: 2013-Q3 | B60: 7075446.4 | C60: 2442357.4 | D60: 489624.41 | E60: 538571.01 | F60: 265685.69 | G60: 206599.1 | I60: 39933.462 | J60: 401454.64 | K60: 1366084.5 | M60: 1326.28 | O60: 4017107 | Q60: =A60 -> 2013-Q3 | R60: =O60/(SUM(B60:K60)-U60) -> 0.32547811 | S60: =(K60-V60)/(SUM(B60:K60)-V61) -> 0.081466227 | U60: 483584.13 | V60: 346878.33
A61: 2013-Q4 | B61: 7222139.7 | C61: 2512915 | D61: 478517.93 | E61: 559464.08 | F61: 273662.06 | G61: 222532.5 | I61: 39388.099 | J61: 393524.41 | K61: 1240641.8 | M61: 1276.16 | O61: 4056270 | Q61: =A61 -> 2013-Q4 | R61: =O61/(SUM(B61:K61)-U61) -> 0.32465025 | S61: =(K61-V61)/(SUM(B61:K61)-V62) -> 0.073436473 | U61: 448508.92 | V61: 314975.46
A62: 2014-Q1 | B62: 7267882 | C62: 2581034.2 | D62: 495184.61 | E62: 559491.55 | F62: 272316.18 | G62: 223447.94 | I62: 40242.463 | J62: 413340.28 | K62: 1331001.6 | M62: 1293.06 | O62: 4053768 | Q62: =A62 -> 2014-Q1 | R62: =O62/(SUM(B62:K62)-U62) -> 0.31887028 | S62: =(K62-V62)/(SUM(B62:K62)-V63) -> 0.07735241 | U62: 471034.47 | V62: 337791.24
A63: 2014-Q2 | B63: 7364359.7 | C63: 2591985 | D63: 505319.21 | E63: 566540.33 | F63: 283836.15 | G63: 228686.2 | I63: 41171.978 | J63: 422875.93 | K63: 1356811.1 | M63: 1288.39 | O63: 4108219 | Q63: =A63 -> 2014-Q2 | R63: =O63/(SUM(B63:K63)-U63) -> 0.31887249 | S63: =(K63-V63)/(SUM(B63:K63)-V64) -> 0.077658772 | U63: 478006.21 | V63: 343871.09
A64: 2014-Q3 | B64: 7342597.9 | C64: 2436134.3 | D64: 484375.72 | E64: 551678.41 | F64: 272658.65 | G64: 219055.59 | I64: 39132.663 | J64: 424043.15 | K64: 1264576.3 | M64: 1281.94 | O64: 4148038 | Q64: =A64 -> 2014-Q3 | R64: =O64/(SUM(B64:K64)-U64) -> 0.32946754 | S64: =(K64-V64)/(SUM(B64:K64)-V65) -> 0.074413982 | U64: 444126.06 | V64: 318113.44
A65: 2014-Q4 | B65: 7271756.9 | C65: 2373228.3 | D65: 473494.89 | E65: 546977.43 | F65: 266527.75 | G65: 209072.05 | I65: 35631.218 | J65: 424365.03 | K65: 1251271.1 | M65: 1201.4 | O65: 4122566 | Q65: =A65 -> 2014-Q4 | R65: =O65/(SUM(B65:K65)-U65) -> 0.33198554 | S65: =(K65-V65)/(SUM(B65:K65)-V66) -> 0.074621988 | U65: 434416.19 | V65: 315367.71
A66: 2015-Q1 | B66: 7269246.7 | C66: 2254273.4 | D66: 474402.28 | E66: 544562.38 | F66: 259819.73 | G66: 197948.97 | I66: 36059.867 | J66: 402418.74 | K66: 1227032.2 | M66: 1218.45 | O66: 4138470 | Q66: =A66 -> 2015-Q1 | R66: =O66/(SUM(B66:K66)-U66) -> 0.33791328 | S66: =(K66-V66)/(SUM(B66:K66)-V67) -> 0.07416395 | U66: 418627.77 | V66: 310399.23
A67: 2015-Q2 | B67: 7273683.7 | C67: 2261523.1 | D67: 441207 | E67: 587155.24 | F67: 256865.08 | G67: 206454.34 | I67: 37685.908 | J67: 395093.43 | K67: 1235690.2 | M67: 1192.35 | O67: 4178877 | Q67: =A67 -> 2015-Q2 | R67: =O67/(SUM(B67:K67)-U67) -> 0.34030356 | S67: =(K67-V67)/(SUM(B67:K67)-V68) -> 0.074933198 | U67: 415506.84 | V67: 306215.24
A68: 2015-Q3 | B68: 7183577.5 | C68: 2188787.4 | D68: 422878.83 | E68: 564871.59 | F68: 233199.63 | G68: 182136.7 | I68: 31612.472 | J68: 375849.38 | K68: 1178358.2 | M68: 1124.31 | O68: 4147458 | Q68: =A68 -> 2015-Q3 | R68: =O68/(SUM(B68:K68)-U68) -> 0.34675466 | S68: =(K68-V68)/(SUM(B68:K68)-V69) -> 0.073406352 | U68: 400486.69 | V68: 291309.8
... A72: 2016-Q3 | B72: 7011474.6 | C72: 2147892.7 | D72: 474248.06 | E72: 515360.95 | F72: 230578.68 | G72: 213648.99 | I72: 21650.672 | J72: 376144.19 | K72: 1423486.8 | M72: 1334.78 | O72: 3899391 | Q72: =A72 -> 2016-Q3 | R72: =O72/(SUM(B72:K72)-U72) -> 0.32611065 | S72: =(K72-V72)/(SUM(B72:K72)-V73) -> 0.0889533 | U72: 457222 | V72: 345832.33
A73: 2016-Q4 | B73: 6931977.6 | C73: 2028548.5 | D73: 426691.29 | E73: 500001.4 | F73: 228405.78 | G73: 200425.36 | H73: 106876.71 | I73: 18780.019 | J73: 275641.46 | K73: 1237643.2 | M73: 1221.55 | O73: 3813442 | Q73: =A73 -> 2016-Q4 | R73: =O73/(SUM(B73:K73)-U73) -> 0.33019533 | S73: =(K73-V73)/(SUM(B73:K73)-V74) -> 0.080656471 | U73: 405942.43 | V73: 299651.62
A74: 2017-Q1 | B74: 6999726.2 | C74: 2072017.8 | D74: 485795.48 | E74: 498006.56 | F74: 226285 | G74: 213235.88 | H74: 112384.83 | I74: 19208.137 | J74: 273028.15 | K74: 1349282.2 | M74: 1219.49 | O74: 3880100 | Q74: =A74 -> 2017-Q1 | R74: =O74/(SUM(B74:K74)-U74) -> 0.32838537 | S74: =(K74-V74)/(SUM(B74:K74)-V75) -> 0.08585581 | U74: 433279.35 | V74: 325526.94
A75: 2017-Q2 | B75: 7060958.4 | C75: 2188687.8 | D75: 504465.65 | E75: 521000.06 | F75: 232426.11 | G75: 214845.29 | H75: 115627.91 | I75: 19645.578 | J75: 259454.32 | K75: 1349000.1 | M75: 1256.59 | O75: 3994397 | Q75: =A75 -> 2017-Q2 | R75: =O75/(SUM(B75:K75)-U75) -> 0.33202832 | S75: =(K75-V75)/(SUM(B75:K75)-V76) -> 0.084427365 | U75: 435821.18 | V75: 324847.04
A76: 2017-Q3 | B76: 7149100.7 | C76: 2232663.8 | D76: 501101.11 | E76: 534625.81 | F76: 240380.98 | G76: 219854.52 | H76: 123928.69 | I76: 19446.382 | J76: 271028.1 | K76: 1399551.6 | M76: 1277.91 | O76: 4070417 | Q76: =A76 -> 2017-Q3 | R76: =O76/(SUM(B76:K76)-U76) -> 0.33245995 | S76: =(K76-V76)/(SUM(B76:K76)-V77) -> 0.086127152 | U76: 448351.38 | V76: 335529.27
A77: 2017-Q4 | B77: 7175397.6 | C77: 2265390.4 | D77: 546623.18 | E77: 542200.07 | F77: 242674.35 | G77: 225334.22 | H77: 140712.75 | I77: 20408.109 | J77: 283943.01 | K77: 1411367.8 | M77: 1275.42 | O77: 4023954 | Q77: =A77 -> 2017-Q4 | R77: =O77/(SUM(B77:K77)-U77) -> 0.32440243 | S77: =(K77-V77)/(SUM(B77:K77)-V78) -> 0.085847795 | U77: 449847.02 | V77: 337595.11
A78: 2018-Q1 | B78: 7298489.7 | C78: 2310578.5 | D78: 528084.9 | E78: 552638.2 | F78: 223340.66 | G78: 215403.83 | H78: 169429.91 | I78: 19453.027 | J78: 286344.55 | K78: 1446119.1 | M78: 1329.28 | O78: 4051690 | Q78: =A78 -> 2018-Q1 | R78: =O78/(SUM(B78:K78)-U78) -> 0.32185989 | S78: =(K78-V78)/(SUM(B78:K78)-V79) -> 0.086453129 | U78: 461516.63 | V78: 346185.35
A79: 2018-Q2 | B79: 7176812.7 | C79: 2246341.3 | D79: 567229.7 | E79: 524310.15 | F79: 223315.67 | G79: 211824.86 | H79: 219094.87 | I79: 17582.612 | J79: 275259.58 | K79: 1371499.7 | M79: 1305.99 | O79: 3988634 | Q79: =A79 -> 2018-Q2 | R79: =O79/(SUM(B79:K79)-U79) -> 0.32186592 | S79: =(K79-V79)/(SUM(B79:K79)-V80) -> 0.083408487 | U79: 441049.01 | V79: 326991.33
A80: 2018-Q3 | B80: 7106618.6 | C80: 2247844.7 | D80: 576112.32 | E80: 516598.9 | F80: 226961.85 | G80: 209299.82 | H80: 213379.44 | I80: 16978.407 | J80: 284326.31 | K80: 1298737.4 | M80: 1213.19 | O80: 4010108 | Q80: =A80 -> 2018-Q3 | R80: =O80/(SUM(B80:K80)-U80) -> 0.3267235 | S80: =(K80-V80)/(SUM(B80:K80)-V81) -> 0.07994182 | U80: 423152.2 | V80: 310464.6
A81: 2018-Q4 | B81: 7089227.8 | C81: 2287938.9 | D81: 581443.06 | E81: 515219.2 | F81: 210706.59 | G81: 198716.81 | H81: 223820.49 | I81: 15259.185 | J81: 299927.23 | K81: 1407701.1 | M81: 1226.28 | O81: 3956774 | Q81: =A81 -> 2018-Q4 | R81: =O81/(SUM(B81:K81)-U81) -> 0.31959091 | S81: =(K81-V81)/(SUM(B81:K81)-V82) -> 0.085919904 | U81: 449214.12 | V81: 334457.13
...

Sheet Variação reservas de ouro acum
B1: Variação acumulada desde 2000 (toneladas)
B2: Afghanistan, Islamic Rep. of | C2: Albania | D2: Algeria | E2: Argentina | F2: Armenia, Rep. of | G2: Aruba, Kingdom of the Netherlands | H2: Australia | I2: Austria | J2: Azerbaijan, Rep. of | K2: Bahamas, The | L2: Bahrain, Kingdom of | M2: Bangladesh | N2: Bank Central Africa States (BEAC)9 | O2: Bank for International Settlements (BIS)2 | P2: Barbados | Q2: Belarus, Rep. of4 | R2: Belgium | S2: Belize | T2: Benin | U2: Bhutan | V2: Bolivia | W2: Bosnia and Herzegovina | X2: Brazil | Y2: Brunei Darussalam | Z2: Bulgaria | AA2: Burkina Faso | AB2: Burundi | AC2: Cabo Verde | AD2: Cambodia | AE2: Cameroon | AF2: Canada | AG2: Cayman Islands | AH2: Central African Rep. | AI2: Chad | AJ2: Chile | AK2: China, P.R.: Hong Kong | AL2: China, P.R.: Macao | AM2: China, P.R.: Mainland | AN2: Colombia | AO2: Comoros, Union of the | AP2: Congo, Dem. Rep. of the | AQ2: Congo, Rep. of | AR2: Costa Rica | AS2: Côte d'Ivoire | AT2: Croatia, Rep. of | AU2: Curaçao and Sint Maarten | AV2: Cyprus | AW2: Czech Rep. | AX2: Denmark | AY2: Dominican Rep. | AZ2: Ecuador | BA2: Egypt, Arab Rep. of | BB2: El Salvador | BC2: Equatorial Guinea, Rep. of | BD2: Eritrea, The State of | BE2: Estonia, Rep. of | BF2: Ethiopia, The Federal Dem. Rep. of | BG2: Euro Area | BH2: European Central Bank | BI2: Fiji, Rep. of | BJ2: Finland | BK2: France | BL2: Gabon | BM2: Georgia | BN2: Germany | BO2: Ghana | BP2: Greece | BQ2: Guatemala | BR2: Guinea | BS2: Guinea-Bissau | BT2: Haiti | BU2: Honduras | BV2: Hungary | BW2: Iceland | BX2: India | BY2: Indonesia | BZ2: International Monetary Fund (IMF)1 | CA2: Iraq | CB2: Ireland | CC2: Israel | CD2: Italy | CE2: Jamaica | CF2: Japan | CG2: Jordan | CH2: Kazakhstan, Rep. of | CI2: Kenya | CJ2: Korea, Rep. of | CK2: Kosovo, Rep. of | CL2: Kuwait | CM2: Kyrgyz Rep. | CN2: Lao People's Dem. Rep. | CO2: Latvia | CP2: Lebanon | CQ2: Lesotho, Kingdom of | CR2: Libya | CS2: Lithuania | CT2: Luxembourg | CU2: Malawi | CV2: Malaysia | CW2: Maldives | CX2: Mali | CY2: Malta | CZ2: Mauritania, Islamic Rep. of | DA2: Mauritius | DB2: Mexico | DC2: Micronesia, Federated States of | DD2: Moldova, Rep. of | DE2: Mongolia | DF2: Montenegro | DG2: Morocco | DH2: Mozambique, Rep. of | DI2: Myanmar | DJ2: Namibia | DK2: Nepal | DL2: Netherlands Antilles | DM2: Netherlands, The | DN2: New Zealand | DO2: Nicaragua | DP2: Niger | DQ2: Nigeria | DR2: North Macedonia, Republic of | DS2: Norway | DT2: Oman | DU2: Pakistan | DV2: Papua New Guinea | DW2: Paraguay | DX2: Peru | DY2: Philippines | DZ2: Poland, Rep. of | EA2: Portugal | EB2: Qatar | EC2: Romania | ED2: Russian Federation | EE2: Rwanda | EF2: San Marino, Rep. of | EG2: Saudi Arabia | EH2: Senegal | EI2: Serbia, Rep. of | EJ2: Singapore | EK2: Slovak Rep. | EL2: Slovenia, Rep. of | EM2: Solomon Islands | EN2: South Africa | EO2: South Sudan, Rep. of | EP2: Spain | EQ2: Sri Lanka | ER2: State Oil Fund of the Republic of Azerbaijan (SOFAZ)8 | ES2: Suriname | ET2: Sweden | EU2: Switzerland | EV2: Syrian Arab Rep. | EW2: Taiwan Province of China | EX2: Tajikistan, Rep. of | EY2: Tanzania, United Rep. of | EZ2: Thailand | FA2: Timor-Leste, Dem. Rep. of | FB2: Togo | FC2: Trinidad and Tobago | FD2: Tunisia | FE2: Türkiye, Rep of5 | FF2: Turkmenistan | FG2: Ukraine | FH2: United Arab Emirates | FI2: United Kingdom | FJ2: United States | FK2: Uruguay | FL2: Uzbekistan, Rep. of | FM2: Venezuela, Rep. Bolivariana de | FN2: Vietnam | FO2: West Bank and Gaza | FP2: Yemen, Rep. of | FQ2: Zambia | FR2: Zimbabwe | FS2: West African Economic and Monetary Union (WAEMU)3 | FT2: Total above (ex Euro Area - row 60)10 | FU2: IMF World6 (may not sum to country total) | FV2: Source: IMF IFS, Respective Central Banks, World Gold Council
A3: Q1 2000
A4: Q2 2000 | B4: #VALUE! | C4: 0.00041709434 | D4: 0 | E4: 0 | F4: 0.023171908 | G4: 0 | H4: 0 | I4: 0 | J4: 0 | K4: 0 | L4: 0 | M4: 0.045877267 | N4: 0 | O4: 0.12845635 | P4: 0 | Q4: #VALUE! | R4: 0 | S4: #VALUE! | T4: #VALUE! | U4: #VALUE! | V4: -0.0001878313 | W4: 0 | X4: 3.1701429 | Y4: 0 | Z4: 0.0056079749 | AA4: #VALUE! | AB4: 0 | AC4: 0 | AD4: 0 | AE4: 0 | AF4: -7.4958788 | AG4: #VALUE! | AH4: 0 | AI4: 0 | AJ4: -33.675469 | AK4: 0 | AL4: 0 | AM4: 0 | AN4: 0 | AO4: 0 | AP4: #VALUE! | AQ4: 0 | AR4: 0.0062206463 | AS4: #VALUE! | AT4: 0 | AU4: #VALUE! | AV4: 0.0031103232 | AW4: 0 | AX4: -7.5580853e-06 | AY4: 0.0092065566 | AZ4: 0 | BA4: 0 | BB4: 0 | BC4: 0 | BD4: 0 | BE4: 0 | BF4: -0.0011368231 | BG4: 0 | BH4: 0 | BI4: 0 | BJ4: 0 | BK4: 0 | BL4: 0 | BM4: 0 | BN4: 0 | BO4: 0 | BP4: 0.18661939 | BQ4: 0.040434201 | BR4: 0 | BS4: #VALUE! | BT4: 0 | BU4: 0 | BV4: 0 | BW4: 0 | BX4: 0 | BY4: 0 | BZ4: 0 | CA4: #VALUE! | CB4: 0 | CC4: 0 | CD4: 0 | CE4: 0 | CF4: 0 | CG4: 0.058380766 | CH4: 0.34567789 | CI4: 0 | CJ4: 0 | CK4: #VALUE! | CL4: 0 | CM4: 0 | CN4: -1.5462749 | CO4: -0.018661939 | CP4: 0 | CQ4: #VALUE! | CR4: 0 | CS4: 0 | CT4: 0 | CU4: 0 | CV4: 0 | CW4: 0 | CX4: #VALUE! | CY4: 0 | CZ4: 0 | DA4: 0 | DB4: 2.4129792 | DC4: 0 | DD4: 0 | DE4: 0.45357532 | DF4: #VALUE! | DG4: 0.0046876613 | DH4: 0.46656154 | DI4: #VALUE! | DJ4: 0 | DK4: 0 | DL4: 0 | DM4: 0 | DN4: 0 | DO4: 0 | DP4: #VALUE! | DQ4: 0 | DR4: 0.012999888 | DS4: -0.12441293 | DT4: 0 | DU4: 0 | DV4: 0 | DW4: 0 | DX4: 0 | DY4: 7.7758079 | DZ4: 0.031103232 | EA4: 0 | EB4: 0 | EC4: 0.62206463 | ED4: -79.188828 | EE4: 0 | EF4: 0 | EG4: 0 | EH4: #VALUE! | EI4: #VALUE! | EJ4: #VALUE! | EK4: 0 | EL4: 0 | EM4: #VALUE! | EN4: -0.62206463 | EO4: #VALUE! | EP4: 0 | EQ4: 1.0264066 | ER4: 0 | ES4: -0.00089999223 | ET4: -0.99999137 | EU4: -51.799553 | EV4: 0 | EW4: -0.62206463 | EX4: 0 | EY4: 0 | EZ4: 1.0264066 | FA4: #VALUE! | FB4: #VALUE! | FC4: 0 | FD4: 0.0047708314 | FE4: -0.02199981 | FF4: #VALUE! | FG4: 0.22083294 | FH4: 0 | FI4: -25.343676 | FJ4: -1.3988367 | FK4: 0.27992908 | FL4: #VALUE! | FM4: 9.0199372 | FN4: 0 | FO4: #VALUE! | FP4: 0 | FQ4: 0 | FR4: -1.3685422 | FS4: 0.31964791 | FT4: -176.52745 | FU4: -176.52745 | FV4: #VALUE!
A5: Q3 2000 | B5: #VALUE! | C5: -0.2575248 | D5: #VALUE! | E5: -9.7353115 | F5: 0.024882585 | G5: 0 | H5: 0.031103232 | I5: -29.983515 | J5: 0 | K5: 0 | L5: 0 | M5: 0.045846163 | N5: 0 | O5: 0.099530341 | P5: 0 | Q5: #VALUE! | R5: 0 | S5: #VALUE! | T5: #VALUE! | U5: #VALUE! | V5: -0.019511363 | W5: 0 | X5: 3.2553928 | Y5: 0 | Z5: 0.0044352586 | AA5: #VALUE! | AB5: 6.2206463e-06 | AC5: 0 | AD5: 0 | AE5: 0 | AF5: -9.3620727 | AG5: #VALUE! | AH5: 0 | AI5: 0 | AJ5: -33.663028 | AK5: 0 | AL5: 0 | AM5: 0 | AN5: -0.0093309695 | AO5: 0 | AP5: #VALUE! | AQ5: 0 | AR5: 0.0030792199 | AS5: #VALUE! | AT5: 0 | AU5: #VALUE! | AV5: 0.0062206463 | AW5: 0 | AX5: 0 | AY5: 0 | AZ5: 0 | BA5: 0 | BB5: 0 | BC5: 0 | BD5: -1.4356086 | BE5: 0 | BF5: -0.0011368231 | BG5: -29.983515 | BH5: 0 | BI5: 0 | BJ5: 0 | BK5: 0 | BL5: 0 | BM5: 0 | BN5: 0 | BO5: 0 | BP5: 0.34213555 | BQ5: 0.018661939 | BR5: 0 | BS5: #VALUE! | BT5: 0 | BU5: 0 | BV5: 0 | BW5: 0 | BX5: 0 | BY5: 0 | BZ5: 0 | CA5: #VALUE! | CB5: 0 | CC5: 0 | CD5: 0 | CE5: 0 | CF5: 9.9529141 | CG5: 0.076949395 | CH5: 1.214061 | CI5: 0.014742932 | CJ5: 0.026999767 | CK5: #VALUE! | CL5: 0 | CM5: -3.0885509e-05 | CN5: -1.8750805 | CO5: -0.018661939 | CP5: 0 | CQ5: #VALUE! | CR5: 0 | CS5: 0 | CT5: 0 | CU5: 0 | CV5: 0 | CW5: 0 | CX5: #VALUE! | CY5: 0 | CZ5: 0 | DA5: 0 | DB5: 1.9109835 | DC5: 0 | DD5: 0 | DE5: 4.5432304 | DF5: #VALUE! | DG5: 0.020195297 | DH5: 0.46654847 | DI5: #VALUE! | DJ5: 0 | DK5: -0.00012441293 | DL5: 0 | DM5: 0 | DN5: 0 | DO5: 0 | DP5: #VALUE! | DQ5: 0 | DR5: 0.12499892 | DS5: -0.12441293 | DT5: 0 | DU5: 0.080868402 | DV5: 0 | DW5: 0 | DX5: 0 | DY5: 13.965351 | DZ5: 0.031103232 | EA5: 0 | EB5: 0 | EC5: 0.87089049 | ED5: -56.296849 | EE5: 0 | EF5: 0 | EG5: 0 | EH5: #VALUE! | EI5: #VALUE! | EJ5: #VALUE! | EK5: 0 | EL5: 0 | EM5: #VALUE! | EN5: 55.05272 | EO5: #VALUE! | EP5: 0 | EQ5: 0.96420018 | ER5: 0 | ES5: 1.1376902 | ET5: 0 | EU5: -120.79896 | EV5: 0 | EW5: -0.62206463 | EX5: 0.091754533 | EY5: 0 | EZ5: 1.0264066 | FA5: #VALUE! | FB5: #VALUE! | FC5: 0.0018661939 | FD5: 0.014101801 | FE5: -0.086999249 | FF5: #VALUE! | FG5: 0.50387235 | FH5: 0 | FI5: -75.571176 | FJ5: -1.9095518 | FK5: -22.923082 | FL5: #VALUE! | FM5: 9.0199372 | FN5: 0 | FO5: #VALUE! | FP5: 0 | FQ5: 0 | FR5: -2.2705359 | FS5: 0.67030574 | FT5: -307.59525 | FU5: -133.95174
A6: Q4 2000 | B6: #VALUE! | C6: -0.25724519 | D6: 0 | E6: -9.7664147 | F6: 0.027992908 | G6: 0 | H6: 0.031103232 | I6: -29.983515 | J6: 0 | K6: 0 | L6: 0 | M6: 0.085938229 | N6: 0 | O6: 0.18661939 | P6: 0 | Q6: #VALUE! | R6: 0 | S6: #VALUE! | T6: #VALUE! | U6: #VALUE! | V6: -0.019511449 | W6: 0 | X6: -49.879337 | Y6: 0 | Z6: 0.011447607 | AA6: #VALUE! | AB6: 0 | AC6: 0 | AD6: 0 | AE6: 0 | AF6: -9.3620727 | AG6: #VALUE! | AH6: 0 | AI6: 0 | AJ6: -33.675469 | AK6: 0 | AL6: 0 | AM6: 0 | AN6: -0.0093309695 | AO6: 0 | AP6: #VALUE! | AQ6: 0 | AR6: 0.0032969426 | AS6: #VALUE! | AT6: 0 | AU6: #VALUE! | AV6: 0.018661939 | AW6: 0 | AX6: 0 | AY6: 0 | AZ6: 0 | BA6: -0.0068738142 | BB6: 0 | BC6: 0 | BD6: -1.4356086 | BE6: 0 | BF6: -0.0011368231 | BG6: -30.045722 | BH6: 0 | BI6: 0 | BJ6: 0 | BK6: 0 | BL6: 0 | BM6: 0 | BN6: 0 | BO6: 0 | BP6: 0.52875494 | BQ6: 0.018661939 | BR6: 1.3207449 | BS6: #VALUE! | BT6: 0 | BU6: 0 | BV6: 0 | BW6: 0 | BX6: 0 | BY6: 0 | BZ6: 0 | CA6: #VALUE! | CB6: 0 | CC6: 0 | CD6: 0 | CE6: 0 | CF6: 9.9529141 | CG6: 0.10211191 | CH6: 1.1776816 | CI6: 0.014742932 | CJ6: 0.026999767 | CK6: #VALUE! | CL6: 0 | CM6: -1.9595036e-06 | CN6: -1.8839672 | CO6: -0.018661939 | CP6: 0 | CQ6: #VALUE! | CR6: 0 | CS6: 0 | CT6: 0 | CU6: 0 | CV6: 0 | CW6: 0 | CX6: #VALUE! | CY6: -0.062206463 | CZ6: 0 | DA6: 0 | DB6: 0.95899173 | DC6: 0 | DD6: 0 | DE6: 2.2495474 | DF6: #VALUE! | DG6: 0.020833318 | DH6: 0.46654847 | DI6: #VALUE! | DJ6: 0 | DK6: -0.00012441293 | DL6: 0 | DM6: -0.031103232 | DN6: 0 | DO6: 0.45583714 | DP6: #VALUE! | DQ6: 0 | DR6: 0.1509987 | DS6: -0.031103232 | DT6: 0 | DU6: 0.080868402 | DV6: 0 | DW6: 0 | DX6: 0 | DY6: 21.351249 | DZ6: 0.031103232 | EA6: 0 | EB6: 0 | EC6: 1.2752325 | ED6: -38.194768 | EE6: 0 | EF6: 0 | EG6: 0 | EH6: #VALUE! | EI6: #VALUE! | EJ6: #VALUE! | EK6: 0 | EL6: 0 | EM6: #VALUE! | EN6: 59.09614 | EO6: #VALUE! | EP6: -0.031103232 | EQ6: 2.3327424 | ER6: 0 | ES6: 0.35369695 | ET6: 0 | EU6: -170.79853 | EV6: 0 | EW6: -0.31103232 | EX6: 0.092376598 | EY6: 0 | EZ6: 1.0264066 | FA6: #VALUE! | FB6: #VALUE! | FC6: 0.0052875494 | FD6: 0.076308264 | FE6: -0.15199869 | FF6: #VALUE! | FG6: 0.712264 | FH6: 0 | FI6: -100.77587 | FJ6: -1.8676869 | FK6: -22.829772 | FL6: #VALUE! | FM6: 7.4647756 | FN6: 0 | FO6: #VALUE! | FP6: 0 | FQ6: 0 | FR6: 0.74647756 | FS6: 1.0395011 | FT6: -216.29087 | FU6: -231.09074
A7: Q1 2001 | B7: #VALUE! | C7: -0.25699916 | D7: 0 | E7: -9.7664147 | F7: 0.031103232 | G7: 0 | H7: 0.031103232 | I7: -59.998134 | J7: 0 | K7: 0 | L7: 0 | M7: 0.085938229 | N7: 0 | O7: -1.9619919 | P7: 0 | Q7: #VALUE! | R7: -0.031103232 | S7: #VALUE! | T7: #VALUE! | U7: #VALUE! | V7: -0.019511414 | W7: 0 | X7: -83.772494 | Y7: 0 | Z7: 0.029546453 | AA7: #VALUE! | AB7: 0 | AC7: 0 | AD7: 0 | AE7: 0 | AF7: -9.9841374 | AG7: #VALUE! | AH7: 0 | AI7: 0 | AJ7: -33.675469 | AK7: 0 | AL7: 0 | AM7: 0 | AN7: -0.0093309695 | AO7: 0 | AP7: #VALUE! | AQ7: 0 | AR7: 0.0029859102 | AS7: #VALUE! | AT7: 0 | AU7: #VALUE! | AV7: 0.012441293 | AW7: -0.031103232 | AX7: -9.6420018e-06 | AY7: 0.0092065566 | AZ7: 0 | BA7: 0 | BB7: 0 | BC7: 0 | BD7: -1.4356086 | BE7: 0 | BF7: -0.0011368231 | BG7: 82.423547 | BH7: 19.470623 | BI7: 0 | BJ7: 0 | BK7: 0 | BL7: 0 | BM7: 0 | BN7: 0 | BO7: 0 | BP7: -8.9888339 | BQ7: 0.018661939 | BR7: 0.76525147 | BS7: #VALUE! | BT7: 0 | BU7: 0 | BV7: 0 | BW7: 0 | BX7: -0.0019999827 | BY7: 0 | BZ7: 0 | CA7: #VALUE! | CB7: 0 | CC7: 0 | CD7: 0 | CE7: 0 | CF7: 9.9529141 | CG7: 0.12786539 | CH7: 1.1167577 | CI7: 0.014742932 | CJ7: 0.04399962 | CK7: #VALUE! | CL7: -0.24882585 | CM7: -1.9595036e-06 | CN7: -1.8928538 | CO7: -0.021772262 | CP7: 0 | CQ7: #VALUE! | CR7: 0 | CS7: 0 | CT7: 0 | CU7: 0 | CV7: 0 | CW7: 0 | CX7: #VALUE! | CY7: -0.062206463 | CZ7: 0 | DA7: 0 | DB7: 0.25399781 | DC7: 0 | DD7: 0 | DE7: 3.1848745 | DF7: #VALUE! | DG7: 0.035406986 | DH7: 0.46654847 | DI7: #VALUE! | DJ7: 0 | DK7: -0.00012441293 | DL7: 0 | DM7: -0.031103232 | DN7: 0 | DO7: 0.45661566 | DP7: #VALUE! | DQ7: 0 | DR7: 0.1509987 | DS7: -0.031103232 | DT7: 0 | DU7: 0.080868402 | DV7: 0 | DW7: 0 | DX7: 0 | DY7: 24.961525 | DZ7: 0.031103232 | EA7: 0 | EB7: 0 | EC7: 1.337439 | ED7: -32.067432 | EE7: 0 | EF7: 0 | EG7: 0 | EH7: #VALUE! | EI7: #VALUE! | EJ7: #VALUE! | EK7: 0 | EL7: 0 | EM7: #VALUE! | EN7: 58.163043 | EO7: #VALUE! | EP7: -0.031103232 | EQ7: 1.4307487 | ER7: 0 | ES7: 0.18229843 | ET7: 0 | EU7: -221.69809 | EV7: 0 | EW7: -0.31103232 | EX7: 0.099219309 | EY7: 0 | EZ7: 1.0264066 | FA7: #VALUE! | FB7: #VALUE! | FC7: 0.0080868402 | FD7: 0.076308264 | FE7: -0.22299808 | FF7: #VALUE! | FG7: 0.90199372 | FH7: 0 | FI7: -151.2014 | FJ7: -1.6810675 | FK7: -30.51227 | FL7: #VALUE! | FM7: 17.41781 | FN7: 0 | FO7: #VALUE! | FP7: 0 | FQ7: 0 | FR7: 0.37323878 | FS7: 1.7033685 | FT7: -364.19391 | FU7: -378.99378
A8: Q2 2001 | B8: #VALUE! | C8: -0.25595658 | D8: 0 | E8: -10.046344 | F8: 0.032036329 | G8: 0 | H8: 0.031103232 | I8: -59.998134 | J8: 0 | K8: 0 | L8: 0 | M8: 0.14864234 | N8: 0 | O8: -1.9909179 | P8: 0 | Q8: #VALUE! | R8: -0.031103232 | S8: #VALUE! | T8: #VALUE! | U8: #VALUE! | V8: -0.019511364 | W8: 0 | X8: -80.914393 | Y8: 0 | Z8: 0.057365276 | AA8: #VALUE! | AB8: 0 | AC8: 0 | AD8: 0 | AE8: 0 | AF8: -9.9841374 | AG8: #VALUE! | AH8: 0 | AI8: 0 | AJ8: -33.675469 | AK8: 0 | AL8: 0 | AM8: 0 | AN8: -0.021772262 | AO8: 0 | AP8: #VALUE! | AQ8: 0 | AR8: 0.0027681876 | AS8: #VALUE! | AT8: 13.125564 | AU8: #VALUE! | AV8: 0.012441293 | AW8: -0.031103232 | AX8: 0 | AY8: 0.0092065566 | AZ8: 0 | BA8: -0.0068738142 | BB8: 0 | BC8: 0 | BD8: -1.4356086 | BE8: 0 | BF8: -4.8210009e-05 | BG8: 80.43294 | BH8: 19.470623 | BI8: 0 | BJ8: 0 | BK8: 0 | BL8: 0 | BM8: 0 | BN8: 0 | BO8: 0 | BP8: -8.9888339 | BQ8: 0.018661939 | BR8: 1.2700261 | BS8: #VALUE! | BT8: 0 | BU8: 0 | BV8: 0 | BW8: 0 | BX8: -0.007999931 | BY8: 0 | BZ8: 0 | CA8: #VALUE! | CB8: 0 | CC8: 0 | CD8: 0 | CE8: 0 | CF8: 11.665899 | CG8: 0.16833069 | CH8: 1.3049649 | CI8: 0.014742932 | CJ8: 0.04399962 | CK8: #VALUE! | CL8: 0 | CM8: 0.00031125004 | CN8: -1.9017404 | CO8: -0.021772262 | CP8: 0 | CQ8: #VALUE! | CR8: 0 | CS8: -0.0093309695 | CT8: 0 | CU8: 0 | CV8: 0 | CW8: 0 | CX8: #VALUE! | CY8: -0.062206463 | CZ8: 0 | DA8: 0 | DB8: -0.3829967 | DC8: 0 | DD8: 0 | DE8: 5.0716494 | DF8: #VALUE! | DG8: 0.035537775 | DH8: 0.46654847 | DI8: #VALUE! | DJ8: 0 | DK8: 0 | DL8: 0 | DM8: -2.0217101 | DN8: 0 | DO8: 0.45892196 | DP8: #VALUE! | DQ8: 0 | DR8: 2.6429772 | DS8: -0.031103232 | DT8: 0 | DU8: 0.080868402 | DV8: 0 | DW8: 0 | DX8: 0 | DY8: 25.93966 | DZ8: 0.031103232 | EA8: 0 | EB8: 0 | EC8: 1.337439 | ED8: -28.49056 | EE8: 0 | EF8: 0 | EG8: 0 | EH8: #VALUE! | EI8: #VALUE! | EJ8: #VALUE! | EK8: -5.0076203 | EL8: 7.5514951 | EM8: #VALUE! | EN8: 57.540979 | EO8: #VALUE! | EP8: -0.031103232 | EQ8: -0.43544524 | ER8: 0 | ES8: 0.55159524 | ET8: 0 | EU8: -269.69767 | EV8: 0 | EW8: -0.31103232 | EX8: 0.099841374 | EY8: 0 | EZ8: 2.0528133 | FA8: #VALUE! | FB8: #VALUE! | FC8: 0.014307487 | FD8: 0.030955616 | FE8: -0.26299773 | FF8: #VALUE! | FG8: 1.2472396 | FH8: 0 | FI8: -172.27811 | FJ8: -3.4923331 | FK8: -43.357905 | FL8: #VALUE! | FM8: 23.016391 | FN8: 0 | FO8: #VALUE! | FP8: 0 | FQ8: 0 | FR8: -3.6701813 | FS8: 2.1517216 | FT8: -402.47672 | FU8: -417.2766
A9: Q3 2001 | B9: #VALUE! | C9: -0.25644832 | D9: 0 | E9: -10.046344 | F9: 0.037323878 | G9: 0 | H9: 0.031103232 | I9: -59.998134 | J9: 0 | K9: 0 | L9: 0 | M9: 0.14864234 | N9: 0 | O9: -1.9619919 | P9: 0 | Q9: #VALUE! | R9: -0.031103232 | S9: #VALUE! | T9: #VALUE! | U9: #VALUE! | V9: -0.019511444 | W9: 0 | X9: -80.883367 | Y9: 0 | Z9: 0.067950795 | AA9: #VALUE! | AB9: -0.50576965 | AC9: 0 | AD9: 0 | AE9: 0 | AF9: -10.668408 | AG9: #VALUE! | AH9: 0 | AI9: 0 | AJ9: -33.675469 | AK9: 0 | AL9: 0 | AM9: 0 | AN9: -0.024882585 | AO9: 0 | AP9: #VALUE! | AQ9: 0 | AR9: 0.0044788654 | AS9: #VALUE! | AT9: 0 | AU9: #VALUE! | AV9: 0.018661939 | AW9: -0.062206463 | AX9: -9.6420018e-06 | AY9: 0.0092065566 | AZ9: 0 | BA9: -0.0068738142 | BB9: 0 | BC9: 0 | BD9: -1.4356076 | BE9: 0 | BF9: -4.8210009e-05 | BG9: 43.57561 | BH9: 19.470623 | BI9: 0 | BJ9: 0 | BK9: 0.031103232 | BL9: 0 | BM9: 0 | BN9: -12.036951 | BO9: 0 | BP9: -8.9888339 | BQ9: 0.05909614 | BR9: 1.942167 | BS9: #VALUE! | BT9: 0 | BU9: 0 | BV9: 0 | BW9: 0.062206463 | BX9: -0.0039999655 | BY9: 0 | BZ9: 0 | CA9: #VALUE! | CB9: 0 | CC9: 0 | CD9: 0 | CE9: 0 | CF9: 11.665899 | CG9: 0.19943392 | CH9: 1.3720361 | CI9: 0.014742932 | CJ9: 0.078999318 | CK9: #VALUE! | CL9: 0 | CM9: 0.00031125004 | CN9: -0.25771249 | CO9: -0.021772262 | CP9: 0 | CQ9: #VALUE! | CR9: 0 | CS9: -0.0093309695 | CT9: 0 | CU9: 0 | CV9: 0 | CW9: 0 | CX9: #VALUE! | CY9: -0.062206463 | CZ9: 0 | DA9: 0 | DB9: -0.97099162 | DC9: 0 | DD9: 0 | DE9: 5.6109172 | DF9: #VALUE! | DG9: 0.051936549 | DH9: -0.93309695 | DI9: #VALUE! | DJ9: 0 | DK9: -0.00031103232 | DL9: 0 | DM9: -26.904295 | DN9: 0 | DO9: 0.46014339 | DP9: #VALUE! | DQ9: 0 | DR9: 2.6579771 | DS9: -0.031103232 | DT9: 0 | DU9: 0.080868402 | DV9: 0 | DW9: 0 | DX9: 0 | DY9: 37.296134 | DZ9: 0.062206463 | EA9: 0.031103232 | EB9: 0 | EC9: 1.3996454 | ED9: -16.889055 | EE9: 0 | EF9: 0 | EG9: 0 | EH9: #VALUE! | EI9: #VALUE! | EJ9: #VALUE! | EK9: -5.0076203 | EL9: 7.5514951 | EM9: #VALUE! | EN9: 57.540979 | EO9: #VALUE! | EP9: -0.031103232 | EQ9: 0.15551616 | ER9: 0 | ES9: 0.16889854 | ET9: 0 | EU9: -320.09724 | EV9: 0 | EW9: -0.31103232 | EX9: 0.1231688 | EY9: 0 | EZ9: 2.7370844 | FA9: #VALUE! | FB9: #VALUE! | FC9: 0.014307487 | FD9: 0.017212124 | FE9: -0.32199722 | FF9: #VALUE! | FG9: 1.4587416 | FH9: 0 | FI9: -212.63458 | FJ9: 10.23147 | FK9: -56.20354 | FL9: #VALUE! | FM9: 26.437747 | FN9: 0 | FO9: #VALUE! | FP9: 0 | FQ9: 0 | FR9: -2.3638456 | FS9: 2.6062331 | FT9: -512.95045 | FU9: -527.75033
A10: Q4 2001 | B10: #VALUE! | C10: -0.28076825 | D10: 0 | E10: -10.077447 | F10: 0.037323878 | G10: 0 | H10: 0.031103232 | I10: -59.998134 | J10: 0 | K10: 0 | L10: 0 | M10: 0.14851793 | N10: 0 | O10: -1.9909179 | P10: 0 | Q10: #VALUE! | R10: -0.031103232 | S10: #VALUE! | T10: #VALUE! | U10: #VALUE! | V10: -0.019511412 | W10: 0 | X10: -81.629326 | Y10: 0 | Z10: 0.063633511 | AA10: #VALUE! | AB10: -0.50576965 | AC10: 0 | AD10: 0 | AE10: 0 | AF10: -13.467699 | AG10: #VALUE! | AH10: 0 | AI10: 0 | AJ10: -33.663028 | AK10: 0 | AL10: 0 | AM10: 105.75099 | AN10: -0.024882585 | AO10: 0 | AP10: #VALUE! | AQ10: 0 | AR10: 0.0035196833 | AS10: #VALUE! | AT10: 0 | AU10: #VALUE! | AV10: 0.0093309695 | AW10: -0.062206463 | AX10: -0.01213026 | AY10: 0.0092065566 | AZ10: 0 | BA10: -0.0068738142 | BB10: 0 | BC10: 0 | BD10: -1.4356086 | BE10: 0 | BF10: -4.8210009e-05 | BG10: 42.70472 | BH10: 19.470623 | BI10: -3.1225023e-17 | BJ10: 0 | BK10: 0 | BL10: 0 | BM10: 0 | BN10: -12.036951 | BO10: 0.031103232 | BP10: -9.4242792 | BQ10: 0.05909614 | BR10: 0.027140991 | BS10: #VALUE! | BT10: 0 | BU10: 9.3309695e-05 | BV10: 0 | BW10: 0.093309695 | BX10: -0.0029999741 | BY10: 0 | BZ10: 0 | CA10: #VALUE! | CB10: 0 | CC10: 0 | CD10: 0 | CE10: 0 | CF10: 11.665899 | CG10: 0.23053715 | CH10: 1.1830899 | CI10: 0.014742932 | CJ10: 0.10699908 | CK10: #VALUE! | CL10: 0 | CM10: 0.00031125004 | CN10: -0.15995948 | CO10: -0.021772262 | CP10: 0 | CQ10: #VALUE! | CR10: 0 | CS10: -0.0062206463 | CT10: 0 | CU10: 0 | CV10: 0 | CW10: 0 | CX10: #VALUE! | CY10: -0.031103232 | CZ10: 0 | DA10: 0 | DB10: 0.3939966 | DC10: 0 | DD10: 0 | DE10: 5.3352978 | DF10: #VALUE! | DG10: 0.051936549 | DH10: -0.15550154 | DI10: #VALUE! | DJ10: 0 | DK10: -0.00031103232 | DL10: 0 | DM10: -27.308637 | DN10: 0 | DO10: 0.46028211 | DP10: #VALUE! | DQ10: 0 | DR10: 2.6949767 | DS10: -0.031103232 | DT10: 0 | DU10: 0.080868402 | DV10: 0 | DW10: 0 | DX10: 0.46176321 | DY10: 44.740257 | DZ10: 0.093309695 | EA10: 0.031103232 | EB10: 0 | EC10: 1.5240583 | ED10: 0.37323878 | EE10: 0 | EF10: 0 | EG10: 0 | EH10: #VALUE! | EI10: #VALUE! | EJ10: #VALUE! | EK10: -5.0076203 | EL10: 7.5514951 | EM10: #VALUE! | EN10: 53.497558 | EO10: #VALUE! | EP10: -0.031103232 | EQ10: -0.18661939 | ER10: 0 | ES10: 0.62869458 | ET10: 0 | EU10: -391.69662 | EV10: 0 | EW10: -0.31103232 | EX10: 0.12534602 | EY10: 0 | EZ10: 4.5410718 | FA10: #VALUE! | FB10: #VALUE! | FC10: 0.023016391 | FD10: 0.021908712 | FE10: -0.33499711 | FF10: #VALUE! | FG10: 1.6298093 | FH10: 0 | FI10: -233.02201 | FJ10: 10.23147 | FK10: -56.20354 | FL10: #VALUE! | FM10: 29.237038 | FN10: 0 | FO10: #VALUE! | FP10: 0 | FQ10: 0 | FR10: -7.6202917 | FS10: 2.8697397 | FT10: -495.46464 | FU10: -510.26452
A11: Q1 2002 | B11: #VALUE! | C11: -0.28011508 | D11: 0 | E11: -10.077447 | F11: 0.037322046 | G11: 0 | H11: 0.031103232 | I11: -59.998134 | J11: 0 | K11: 0 | L11: 0 | M11: 0.14851793 | N11: 0 | O11: -2.0490809 | P11: 0 | Q11: #VALUE! | R11: -0.062206463 | S11: #VALUE! | T11: #VALUE! | U11: #VALUE! | V11: -0.88450379 | W11: 0 | X11: -81.602591 | Y11: 0 | Z11: 0.0017508009 | AA11: #VALUE! | AB11: -0.50576965 | AC11: 0 | AD11: 0 | AE11: 0 | AF11: -16.422506 | AG11: #VALUE! | AH11: 0 | AI11: 0 | AJ11: -35.591428 | AK11: 0 | AL11: 0 | AM11: 105.75099 | AN11: -0.024882585 | AO11: 0 | AP11: #VALUE! | AQ11: 0 | AR11: 0.0039854202 | AS11: #VALUE! | AT11: 0 | AU11: #VALUE! | AV11: 0.040434201 | AW11: -0.093309695 | AX11: -0.01213026 | AY11: 0.0092065566 | AZ11: 0 | BA11: -0.0068738142 | BB11: 0 | BC11: 0 | BD11: -1.4356126 | BE11: 0 | BF11: -4.8210009e-05 | BG11: 34.337951 | BH11: 19.470623 | BI11: -3.1225023e-17 | BJ11: 0.031103232 | BK11: 0 | BL11: 0 | BM11: 0 | BN11: -20.434823 | BO11: 0.031103232 | BP11: -9.393176 | BQ11: 0.05909614 | BR11: -0.29266244 | BS11: #VALUE! | BT11: 0 | BU11: 9.3309695e-05 | BV11: 0 | BW11: 0.08873752 | BX11: -0.0039999655 | BY11: 0 | BZ11: 0 | CA11: #VALUE! | CB11: 0 | CC11: 0 | CD11: 0 | CE11: 0 | CF11: 11.665899 | CG11: 0.26164038 | CH11: -1.2643662 | CI11: 0.014742932 | CJ11: 0.12199895 | CK11: #VALUE! | CL11: 0 | CM11: 0.00031125004 | CN11: -0.15995948 | CO11: -0.021772262 | CP11: 0 | CQ11: #VALUE! | CR11: 0 | CS11: -0.0031103232 | CT11: 0 | CU11: 0 | CV11: 0 | CW11: 0 | CX11: #VALUE! | CY11: -0.050927592 | CZ11: 0 | DA11: 0 | DB11: -0.47799588 | DC11: 0 | DD11: 0 | DE11: 1.3186713 | DF11: #VALUE! | DG11: 0.051936549 | DH11: -0.31103232 | DI11: #VALUE! | DJ11: 0 | DK11: -0.00031103232 | DL11: 0 | DM11: -27.308637 | DN11: 0 | DO11: 0.46028211 | DP11: #VALUE! | DQ11: 0 | DR11: 2.7109766 | DS11: -0.062206463 | DT11: 0 | DU11: 0.080868402 | DV11: 0 | DW11: 0 | DX11: 0.46176321 | DY11: 45.760909 | DZ11: 0.093309695 | EA11: 0.031103232 | EB11: 0 | EC11: 1.5240583 | ED11: 4.1056266 | EE11: 0 | EF11: 0 | EG11: 0 | EH11: #VALUE! | EI11: #VALUE! | EJ11: #VALUE! | EK11: -5.0076203 | EL11: 7.5514951 | EM11: #VALUE! | EN11: 53.808591 | EO11: #VALUE! | EP11: -0.031103232 | EQ11: -0.90199372 | ER11: 0 | ES11: 0.51469556 | ET11: 0 | EU11: -461.39602 | EV11: 0 | EW11: -0.31103232 | EX11: 0.22052191 | EY11: 0 | EZ11: 4.5410718 | FA11: #VALUE! | FB11: #VALUE! | FC11: 0.025815682 | FD11: 0.021908712 | FE11: -0.33499711 | FF11: #VALUE! | FG11: 1.7977668 | FH11: 0 | FI11: -273.79066 | FJ11: 10.23147 | FK11: -56.20354 | FL11: #VALUE! | FM11: 42.92246 | FN11: 0 | FO11: #VALUE! | FP11: 0 | FQ11: 0 | FR11: -10.543996 | FS11: 3.3665827 | FT11: -611.45232 | FU11: -627.94607
A12: Q2 2002 | B12: #VALUE! | C12: -0.27993282 | D12: 0 | E12: -10.065006 | F12: 0.037322046 | G12: 0 | H12: 0.031103232 | I12: -89.981649 | J12: 0 | K12: 0 | L12: 0 | M12: 0.17651084 | N12: 0 | O12: -2.0780069 | P12: 0 | Q12: #VALUE! | R12: -0.093309695 | S12: #VALUE! | T12: #VALUE! | U12: #VALUE! | V12: -0.88450373 | W12: 0 | X12: -81.587227 | Y12: 0 | Z12: -0.039948182 | AA12: #VALUE! | AB12: -0.50576965 | AC12: 0 | AD12: 0 | AE12: 0 | AF12: -19.377313 | AG12: #VALUE! | AH12: 0 | AI12: 0 | AJ12: -35.591428 | AK12: 0 | AL12: 0 | AM12: 105.12892 | AN12: -0.027992908 | AO12: 0 | AP12: #VALUE! | AQ12: 0 | AR12: 0.0023160972 | AS12: #VALUE! | AT12: 0 | AU12: #VALUE! | AV12: 0.031103232 | AW12: -0.093309695 | AX12: -0.01213026 | AY12: 0.0092065566 | AZ12: 0 | BA12: -0.0068738142 | BB12: 0 | BC12: 0 | BD12: -1.4356076 | BE12: 0 | BF12: 1.2618721 | BG12: -7.0405135 | BH12: 19.470623 | BI12: -3.1225023e-17 | BJ12: 0.031103232 | BK12: 0 | BL12: 0 | BM12: 0 | BN12: -22.798669 | BO12: 0.031103232 | BP12: -9.4242792 | BQ12: 0.19595036 | BR12: 0.36762807 | BS12: #VALUE! | BT12: 0 | BU12: 9.3309695e-05 | BV12: 0 | BW12: 0.095962801 | BX12: -0.0039999655 | BY12: 0 | BZ12: 0 | CA12: #VALUE! | CB12: 0 | CC12: 0 | CD12: 0 | CE12: 0 | CF12: 11.665899 | CG12: 0.32362913 | CH12: -1.86629 | CI12: 0.014742932 | CJ12: 0.12199895 | CK12: #VALUE! | CL12: 0 | CM12: 0.00031125004 | CN12: -0.15995948 | CO12: -0.021772262 | CP12: 0 | CQ12: #VALUE! | CR12: 0 | CS12: -0.0031103232 | CT12: 0 | CU12: 0 | CV12: 0 | CW12: 0 | CX12: #VALUE! | CY12: -0.060904513 | CZ12: 0 | DA12: 0 | DB12: -0.84999267 | DC12: 0 | DD12: 0 | DE12: 0.88934192 | DF12: #VALUE! | DG12: 0.067488165 | DH12: 1.5551762 | DI12: #VALUE! | DJ12: 0 | DK12: -0.00018661939 | DL12: 0 | DM12: -36.266368 | DN12: 0 | DO12: 0.46028211 | DP12: #VALUE! | DQ12: 0 | DR12: 2.7649761 | DS12: -0.062206463 | DT12: -9.0199372 | DU12: 0.1617368 | DV12: 0 | DW12: 0 | DX12: 0.46176321 | DY12: 52.154179 | DZ12: 0.093309695 | EA12: 0.062206463 | EB12: 0 | EC12: 1.5551616 | ED12: -35.79982 | EE12: 0 | EF12: 0 | EG12: 0 | EH12: #VALUE! | EI12: #VALUE! | EJ12: #VALUE! | EK12: -5.0076203 | EL12: 7.5460052 | EM12: #VALUE! | EN12: 53.497558 | EO12: #VALUE! | EP12: -0.062206463 | EQ12: -0.87089049 | ER12: 0 | ES12: 0.56419513 | ET12: 0 | EU12: -529.99543 | EV12: 0 | EW12: -0.31103232 | EX12: -0.068738142 | EY12: 0 | EZ12: 5.1631364 | FA12: #VALUE! | FB12: #VALUE! | FC12: 0.02761967 | FD12: 0.011613542 | FE12: -0.33499711 | FF12: #VALUE! | FG12: 1.9657242 | FH12: 0 | FI12: -274.1791 | FJ12: 10.23147 | FK12: -56.20354 | FL12: #VALUE! | FM12: 15.551616 | FN12: 0 | FO12: #VALUE! | FP12: 0 | FQ12: 0 | FR12: -9.8597244 | FS12: 3.7439271 | FT12: -791.13517 | FU12: -807.62893
A13: Q3 2002 | B13: #VALUE! | C13: -0.28408976 | D13: 0 | E13: -10.067805 | F13: 0.037322046 | G13: 0 | H13: 0.031103232 | I13: -89.981649 | J13: 0 | K13: 0 | L13: 0 | M13: 0.20179777 | N13: 0 | O13: -2.1069329 | P13: 0 | Q13: #VALUE! | R13: -0.093309695 | S13: #VALUE! | T13: #VALUE! | U13: #VALUE! | V13: -0.88450373 | W13: 0 | X13: -81.904462 | Y13: 0 | Z13: -0.039948182 | AA13: #VALUE! | AB13: -0.50576965 | AC13: 0 | AD13: 0 | AE13: 0 | AF13: -22.145501 | AG13: #VALUE! | AH13: 0 | AI13: 0 | AJ13: -35.712731 | AK13: 0 | AL13: 0 | AM13: 105.12892 | AN13: -0.024882585 | AO13: 0 | AP13: #VALUE! | AQ13: 0 | AR13: 0.0047630865 | AS13: #VALUE! | AT13: 0 | AU13: #VALUE! | AV13: 0.040434201 | AW13: -0.12441293 | AX13: -0.01213026 | AY13: 0.0093309695 | AZ13: 0 | BA13: -0.0068738142 | BB13: 0 | BC13: 0 | BD13: -2.6386522 | BE13: 0 | BF13: 1.2618721 | BG13: -7.0094103 | BH13: 19.470623 | BI13: -3.1225023e-17 | BJ13: 0 | BK13: 0 | BL13: 0 | BM13: 0 | BN13: -22.798669 | BO13: 0.031103232 | BP13: -9.3620727 | BQ13: 0.11819228 | BR13: 0.68195733 | BS13: #VALUE! | BT13: 0 | BU13: 9.3309695e-05 | BV13: 0 | BW13: 0.10257535 | BX13: -0.0039999655 | BY13: 0 | BZ13: 0 | CA13: #VALUE! | CB13: 0 | CC13: 0 | CD13: 0 | CE13: 0 | CF13: 11.665899 | CG13: 0.35495008 | CH13: -1.8435347 | CI13: 0.014742932 | CJ13: 0.19499832 | CK13: #VALUE! | CL13: 0 | CM13: 0.00031125004 | CN13: -0.15995948 | CO13: -0.021772262 | CP13: 0 | CQ13: #VALUE! | CR13: 0 | CS13: -0.0031103232 | CT13: 0 | CU13: 0 | CV13: 0 | CW13: 0 | CX13: #VALUE! | CY13: -0.10234214 | CZ13: 0 | DA13: 0 | DB13: 0.79399315 | DC13: 0 | DD13: 0 | DE13: 4.6467171 | DF13: #VALUE! | DG13: 0.073358931 | DH13: 1.5544991 | DI13: #VALUE! | DJ13: 0 | DK13: -0.00018661939 | DL13: 0 | DM13: -36.266368 | DN13: 0 | DO13: 0.46028211 | DP13: #VALUE! | DQ13: 0 | DR13: 2.8199757 | DS13: -0.062206463 | DT13: -9.0199372 | DU13: 0.1617368 | DV13: 0 | DW13: 0 | DX13: 0.46176321 | DY13: 59.944667 | DZ13: 0.093309695 | EA13: 0.062206463 | EB13: 0 | EC13: 1.617368 | ED13: -35.70651 | EE13: 0 | EF13: 0 | EG13: 0 | EH13: #VALUE! | EI13: #VALUE! | EJ13: #VALUE! | EK13: -5.0076203 | EL13: 7.5444595 | EM13: #VALUE! | EN13: 49.454138 | EO13: #VALUE! | EP13: -0.062206463 | EQ13: -1.0886131 | ER13: 0 | ES13: -6.8087413 | ET13: 0 | EU13: -603.0948 | EV13: 0 | EW13: -0.31103232 | EX13: -0.068738142 | EY13: 0 | EZ13: 5.1631364 | FA13: #VALUE! | FB13: #VALUE! | FC13: 0.02761967 | FD13: 0.0069480576 | FE13: -0.3359971 | FF13: #VALUE! | FG13: 2.136792 | FH13: 0 | FI13: -274.31294 | FJ13: 10.23147 | FK13: -56.20354 | FL13: #VALUE! | FM13: 13.37439 | FN13: 0 | FO13: #VALUE! | FP13: 0 | FQ13: 0 | FR13: -9.4864856 | FS13: 4.2485148 | FT13: -870.71729 | FU13: -887.21105
A14: Q4 2002 | B14: #VALUE! | C14: -1.2180176 | D14: 0 | E14: -10.077447 | F14: 0.037322046 | G14: 0 | H14: 0.031103232 | I14: -89.981649 | J14: 0 | K14: 0 | L14: 0 | M14: 0.20170446 | N14: 1.8661939e-05 | O14: -2.1070275 | P14: 0 | Q14: #VALUE! | R14: -0.12441293 | S14: #VALUE! | T14: #VALUE! | U14: #VALUE! | V14: -0.88450373 | W14: 0 | X14: -82.168847 | Y14: 0 | Z14: -0.039948182 | AA14: #VALUE! | AB14: -0.50576965 | AC14: 0 | AD14: 0 | AE14: 0 | AF14: -27.557463 | AG14: #VALUE! | AH14: 0 | AI14: 6.2206463e-06 | AJ14: -35.715841 | AK14: 0 | AL14: 0 | AM14: 204.9703 | AN14: -0.024882585 | AO14: 0 | AP14: #VALUE! | AQ14: -6.2206463e-06 | AR14: 0.0085316819 | AS14: #VALUE! | AT14: 0 | AU14: #VALUE! | AV14: 0.034213555 | AW14: -0.12441293 | AX14: -0.043233492 | AY14: 0.0092065566 | AZ14: 0 | BA14: 0 | BB14: 0 | BC14: 0 | BD14: -2.6386522 | BE14: 0 | BF14: 1.2618721 | BG14: -46.075069 | BH14: 19.470623 | BI14: -3.1225023e-17 | BJ14: 0 | BK14: 0.062206463 | BL14: -9.3309695e-06 | BM14: 0 | BN14: -22.798669 | BO14: 0.031103232 | BP14: -9.6420018 | BQ14: 0.031103232 | BR14: 7.4305188 | BS14: #VALUE! | BT14: 0 | BU14: 9.3309695e-05 | BV14: 0 | BW14: 0.10936829 | BX14: -0.0039999655 | BY14: 0 | BZ14: 0 | CA14: #VALUE! | CB14: 0 | CC14: 0 | CD14: 0 | CE14: 0 | CF14: 11.665899 | CG14: 0.38288078 | CH14: -2.9000617 | CI14: 0.015551616 | CJ14: 0.19499832 | CK14: #VALUE! | CL14: 0 | CM14: 0.00031125004 | CN14: -0.15995948 | CO14: -0.021772262 | CP14: 0 | CQ14: #VALUE! | CR14: 0 | CS14: -0.0031103232 | CT14: 0 | CU14: 0 | CV14: 0 | CW14: 0 | CX14: #VALUE! | CY14: -0.075929676 | CZ14: 0 | DA14: 0 | DB14: 0.19099835 | DC14: 0 | DD14: 0 | DE14: 4.0392949 | DF14: #VALUE! | DG14: 0.082324407 | DH14: 0.31104693 | DI14: #VALUE! | DJ14: 0 | DK14: -0.00018661939 | DL14: 0 | DM14: -60.15365 | DN14: 0 | DO14: 0.46028211 | DP14: #VALUE! | DQ14: 0 | DR14: 2.8199757 | DS14: -0.062206463 | DT14: -9.0199372 | DU14: 0.1617368 | DV14: 0 | DW14: 0 | DX14: 0.46176321 | DY14: 68.013872 | DZ14: 0.12441293 | EA14: -14.867345 | EB14: 0 | EC14: 1.6484713 | ED14: -34.928929 | EE14: 0 | EF14: 0 | EG14: 0 | EH14: #VALUE! | EI14: #VALUE! | EJ14: #VALUE! | EK14: -5.0076203 | EL14: 7.5444552 | EM14: #VALUE! | EN14: 49.143106 | EO14: #VALUE! | EP14: -0.062206463 | EQ14: -1.3996454 | ER14: 0 | ES14: -6.9770398 | ET14: 0 | EU14: -673.49419 | EV14: 0 | EW14: -0.31103232 | EX14: -0.068738142 | EY14: 0 | EZ14: 5.1631364 | FA14: #VALUE! | FB14: #VALUE! | FC14: 0.02954807 | FD14: 0.0069430189 | FE14: -0.33499711 | FF14: #VALUE! | FG14: 9.9312619 | FH14: 0 | FI14: -274.39844 | FJ14: 10.23147 | FK14: -56.191098 | FL14: #VALUE! | FM14: 17.41781 | FN14: 0 | FO14: #VALUE! | FP14: 0 | FQ14: 0 | FR14: -9.393176 | FS14: 4.5919256 | FT14: -863.3459 | FU14: -879.83965
A15: Q1 2003 | B15: #VALUE! | C15: -1.579572 | D15: 0 | E15: -10.069197 | F15: 0.037322046 | G15: 0 | H15: 0.031103232 | I15: -89.981649 | J15: 0 | K15: 0 | L15: 0 | M15: 0.20484588 | N15: 1.8661939e-05 | O15: -7.0715008 | P15: 0 | Q15: #VALUE! | R15: -0.12441293 | S15: #VALUE! | T15: #VALUE! | U15: #VALUE! | V15: -0.88450373 | W15: 0 | X15: -82.162496 | Y15: 0 | Z15: -0.036303225 | AA15: #VALUE! | AB15: -0.50576965 | AC15: 0 | AD15: 0 | AE15: 0 | AF15: -30.387857 | AG15: #VALUE! | AH15: 0 | AI15: 6.2206463e-06 | AJ15: -35.715841 | AK15: 0 | AL15: 0 | AM15: 204.9703 | AN15: -0.031103232 | AO15: 0 | AP15: #VALUE! | AQ15: -6.2206463e-06 | AR15: -0.00069118293 | AS15: #VALUE! | AT15: 0 | AU15: #VALUE! | AV15: 0.034213555 | AW15: -0.15551616 | AX15: -0.03060558 | AY15: 0.0093309695 | AZ15: 0 | BA15: 0 | BB15: 0 | BC15: 0 | BD15: -2.6386522 | BE15: 0 | BF15: 1.2618795 | BG15: -85.171831 | BH15: 19.470623 | BI15: -3.1225023e-17 | BJ15: 0 | BK15: 0.062206463 | BL15: -9.3309695e-06 | BM15: 0 | BN15: -22.798669 | BO15: 0.031103232 | BP15: -9.797518 | BQ15: 0.12752325 | BR15: 7.4305188 | BS15: #VALUE! | BT15: 0 | BU15: 9.3309695e-05 | BV15: 0 | BW15: 0.11601505 | BX15: -0.0039999655 | BY15: 0 | BZ15: 0 | CA15: #VALUE! | CB15: 0 | CC15: 0 | CD15: 0 | CE15: 0 | CF15: 11.665899 | CG15: 0.39354919 | CH15: -3.3585892 | CI15: 0.015551616 | CJ15: 0.26999767 | CK15: #VALUE! | CL15: 0 | CM15: 0.00031125004 | CN15: 1.2352426 | CO15: -0.021772262 | CP15: 0 | CQ15: #VALUE! | CR15: 0 | CS15: -0.0031103232 | CT15: 0.031103232 | CU15: 0 | CV15: 0 | CW15: 0 | CX15: #VALUE! | CY15: -0.013759603 | CZ15: 0 | DA15: 0 | DB15: -0.35499694 | DC15: 0 | DD15: 0 | DE15: 2.4694908 | DF15: #VALUE! | DG15: 0.082342851 | DH15: 0.93311157 | DI15: #VALUE! | DJ15: 0 | DK15: -0.00018661939 | DL15: 0 | DM15: -69.266897 | DN15: 0 | DO15: 0.46028211 | DP15: #VALUE! | DQ15: 0 | DR15: 2.8199757 | DS15: -0.093309695 | DT15: -9.0199372 | DU15: 0.1617368 | DV15: 0 | DW15: 0 | DX15: 0.46176321 | DY15: 70.941153 | DZ15: 0.12441293 | EA15: -44.726447 | EB15: 0 | EC15: 1.6484713 | ED15: -35.364374 | EE15: 0 | EF15: 0 | EG15: 0 | EH15: #VALUE! | EI15: #VALUE! | EJ15: #VALUE! | EK15: -5.0076203 | EL15: 7.5444552 | EM15: #VALUE! | EN15: 43.544524 | EO15: #VALUE! | EP15: -0.062206463 | EQ15: -3.7323878 | ER15: 0 | ES15: -7.0358393 | ET15: 0 | EU15: -743.99358 | EV15: 0 | EW15: -0.31103232 | EX15: -0.068738142 | EY15: 0 | EZ15: 5.1631364 | FA15: #VALUE! | FB15: #VALUE! | FC15: 0.034244658 | FD15: 0.0081743336 | FE15: -0.33499711 | FF15: #VALUE! | FG15: 10.242294 | FH15: 0 | FI15: -274.61687 | FJ15: -4.1500142 | FK15: -56.190986 | FL15: #VALUE! | FM15: 20.217101 | FN15: 0 | FO15: #VALUE! | FP15: 0 | FQ15: 0 | FR15: -13.778732 | FS15: 4.5917079 | FT15: -999.60541 | FU15: -1016.0992
A16: Q2 2003 | B16: #VALUE! | C16: -1.5795294 | D16: 0 | E16: -10.069643 | F16: 0.037322046 | G16: 0 | H16: 0.031103232 | I16: -89.981649 | J16: 0 | K16: 0 | L16: 0 | M16: 0.18503312 | N16: 1.8661939e-05 | O16: -5.5248055 | P16: 0 | Q16: #VALUE! | R16: -0.21772262 | S16: #VALUE! | T16: #VALUE! | U16: #VALUE! | V16: -0.88450373 | W16: 0 | X16: -82.157619 | Y16: 0 | Z16: -0.036303225 | AA16: #VALUE! | AB16: -0.50576965 | AC16: 0 | AD16: 0 | AE16: 0 | AF16: -36.5774 | AG16: #VALUE! | AH16: 0 | AI16: 6.2206463e-06 | AJ16: -35.715841 | AK16: 0 | AL16: 0 | AM16: 204.9703 | AN16: -0.031103232 | AO16: 0 | AP16: #VALUE! | AQ16: -6.2206463e-06 | AR16: 0.00018879019 | AS16: #VALUE! | AT16: 0 | AU16: #VALUE! | AV16: 0.037323878 | AW16: -0.093309695 | AX16: -0.028509004 | AY16: 0.0093309695 | AZ16: 0 | BA16: 0 | BB16: 0 | BC16: 0 | BD16: -2.6386522 | BE16: 0 | BF16: 1.2618721 | BG16: -132.9464 | BH16: 19.470623 | BI16: -3.1225023e-17 | BJ16: 0 | BK16: 0.062206463 | BL16: -9.3309695e-06 | BM16: 0 | BN16: -25.629063 | BO16: 0.031103232 | BP16: -9.797518 | BQ16: 0.13996454 | BR16: 7.4305188 | BS16: #VALUE! | BT16: 0 | BU16: 9.3309695e-05 | BV16: 0 | BW16: 0.12242854 | BX16: -0.0039999655 | BY16: 0 | BZ16: 0 | CA16: #VALUE! | CB16: 0 | CC16: 0 | CD16: 0 | CE16: 0 | CF16: 11.665899 | CG16: 0.40763895 | CH16: 15.138225 | CI16: 0.015551616 | CJ16: 0.26999767 | CK16: #VALUE! | CL16: 0 | CM16: 0.00031125004 | CN16: 1.2352426 | CO16: -0.021772262 | CP16: 0 | CQ16: #VALUE! | CR16: 0 | CS16: -0.0031103232 | CT16: 0.031103232 | CU16: 0 | CV16: 0 | CW16: 0 | CX16: #VALUE! | CY16: -0.075966066 | CZ16: 0 | DA16: 0 | DB16: -0.73099369 | DC16: 0 | DD16: 0 | DE16: 3.3280996 | DF16: #VALUE! | DG16: 0.082342851 | DH16: 0.31104693 | DI16: #VALUE! | DJ16: 0 | DK16: -0.00018661939 | DL16: 0 | DM16: -69.298 | DN16: 0 | DO16: 0.46028211 | DP16: #VALUE! | DQ16: 0 | DR16: 2.8199757 | DS16: -0.093309695 | DT16: -9.0199372 | DU16: 0.1617368 | DV16: 0 | DW16: 0 | DX16: 0.46176321 | DY16: 68.450188 | DZ16: 0.093309695 | EA16: -89.515101 | EB16: 0 | EC16: 1.6484713 | ED16: -34.960032 | EE16: 0 | EF16: 0 | EG16: 0 | EH16: #VALUE! | EI16: #VALUE! | EJ16: #VALUE! | EK16: -5.0076203 | EL16: 7.5444552 | EM16: #VALUE! | EN16: -0.62206463 | EO16: #VALUE! | EP16: -0.093309695 | EQ16: -3.7323878 | ER16: 0 | ES16: -7.0365393 | ET16: 0 | EU16: -812.19299 | EV16: 0 | EW16: -0.31103232 | EX16: 0.088022146 | EY16: 0 | EZ16: 5.1631364 | FA16: #VALUE! | FB16: #VALUE! | FC16: 0.035924233 | FD16: 0.0081743336 | FE16: -0.33499711 | FF16: #VALUE! | FG16: 10.242294 | FH16: -6.1895431 | FI16: -275.03025 | FJ16: -3.4903735 | FK16: -56.191004 | FL16: #VALUE! | FM16: 43.233492 | FN16: 0 | FO16: #VALUE! | FP16: 0 | FQ16: 0 | FR16: -13.778732 | FS16: 4.5916146 | FT16: -1134.0051 | FU16: -1150.4988
A17: Q3 2003 | B17: #VALUE! | C17: -1.5794865 | D17: 0 | E17: -10.070024 | F17: 0.037322046 | G17: 0 | H17: 0.031103232 | I17: -89.981649 | J17: 0 | K17: 0 | L17: 0 | M17: 0.19038288 | N17: 1.8661939e-05 | O17: -5.5270339 | P17: 0 | Q17: #VALUE! | R17: -0.21772262 | S17: #VALUE! | T17: #VALUE! | U17: #VALUE! | V17: -0.88450379 | W17: 0 | X17: -82.166697 | Y17: 0 | Z17: -0.036303225 | AA17: #VALUE! | AB17: -0.50576965 | AC17: 0 | AD17: 0 | AE17: 0 | AF17: -40.80744 | AG17: #VALUE! | AH17: 0 | AI17: 6.2206463e-06 | AJ17: -35.715841 | AK17: 0 | AL17: 0 | AM17: 204.9703 | AN17: -0.031103232 | AO17: 0 | AP17: #VALUE! | AQ17: -6.2206463e-06 | AR17: 0.0045577876 | AS17: #VALUE! | AT17: 0 | AU17: #VALUE! | AV17: 0.049765171 | AW17: -0.12441293 | AX17: -0.043048272 | AY17: 0.0092065566 | AZ17: 0 | BA17: 0 | BB17: 0 | BC17: 0 | BD17: -2.6386522 | BE17: 0 | BF17: 1.2618721 | BG17: -157.36243 | BH17: 19.470623 | BI17: -3.1225023e-17 | BJ17: 0 | BK17: 0.031103232 | BL17: -9.3309695e-06 | BM17: 0 | BN17: -29.081522 | BO17: 0.031103232 | BP17: -24.820379 | BQ17: 0.13996454 | BR17: 7.4305188 | BS17: #VALUE! | BT17: 0 | BU17: 9.3309695e-05 | BV17: 0 | BW17: 0.12844079 | BX17: -0.0039999655 | BY17: 0 | BZ17: 0 | CA17: #VALUE! | CB17: 0 | CC17: 0 | CD17: 0 | CE17: 0 | CF17: 11.665899 | CG17: 0.41613014 | CH17: -2.6556174 | CI17: 0.015551616 | CJ17: 0.34499702 | CK17: #VALUE! | CL17: 0 | CM17: 2.1772262e-07 | CN17: 1.2352426 | CO17: -0.021772262 | CP17: 0 | CQ17: #VALUE! | CR17: 0 | CS17: -0.0031103232 | CT17: -0.031103232 | CU17: 0 | CV17: 0 | CW17: 0 | CX17: #VALUE! | CY17: -0.075966066 | CZ17: 0 | DA17: 0 | DB17: -1.0799907 | DC17: 0 | DD17: 0 | DE17: 2.4190632 | DF17: #VALUE! | DG17: 0.083830581 | DH17: -0.3110177 | DI17: #VALUE! | DJ17: 0 | DK17: -0.00018661939 | DL17: 0 | DM17: -75.114304 | DN17: 0 | DO17: 0.46028211 | DP17: #VALUE! | DQ17: 0 | DR17: -0.578995 | DS17: -0.093309695 | DT17: -9.0199372 | DU17: 0.23638456 | DV17: 0 | DW17: 0 | DX17: 0.46176321 | DY17: 58.974526 | DZ17: 0.093309695 | EA17: -89.546204 | EB17: 0 | EC17: 1.6484713 | ED17: -34.493484 | EE17: 0 | EF17: 0 | EG17: 0 | EH17: #VALUE! | EI17: #VALUE! | EJ17: #VALUE! | EK17: -5.0076203 | EL17: 7.5436188 | EM17: #VALUE! | EN17: -0.93309695 | EO17: #VALUE! | EP17: -0.093309695 | EQ17: -2.9229054 | ER17: 0 | ES17: -6.9728398 | ET17: 0 | EU17: -885.59236 | EV17: 0 | EW17: 1.5551616 | EX17: 0.13312183 | EY17: 0 | EZ17: 5.1631364 | FA17: #VALUE! | FB17: #VALUE! | FC17: 0.03708034 | FD17: 0.0081743336 | FE17: -0.33499711 | FF17: #VALUE! | FG17: 9.6202295 | FH17: -6.1895431 | FI17: -275.03025 | FJ17: -3.5678016 | FK17: -56.191286 | FL17: #VALUE! | FM17: 23.949488 | FN17: 0 | FO17: #VALUE! | FP17: 0 | FQ17: 0 | FR17: -13.778732 | FS17: 4.5916146 | FT17: -1288.6228 | FU17: -1305.1166
... A19: Q1 2004 | B19: #VALUE! | C19: -1.5794025 | D19: 0 | E19: 18.247734 | F19: -1.3592112 | G19: 0 | H19: 0.031103232 | I19: -89.981649 | J19: 0 | K19: 0 | L19: 0 | M19: 0.20204659 | N19: 1.8661939e-05 | O19: -4.7166044 | P19: 0 | Q19: #VALUE! | R19: -0.27992908 | S19: #VALUE! | T19: #VALUE! | U19: #VALUE! | V19: -0.88450379 | W19: 0 | X19: -82.160443 | Y19: 0 | Z19: -0.058075488 | AA19: #VALUE! | AB19: -0.50576965 | AC19: 0 | AD19: 0 | AE19: 0 | AF19: -42.798047 | AG19: #VALUE! | AH19: 0 | AI19: 6.2206463e-06 | AJ19: -35.715841 | AK19: 0 | AL19: 0 | AM19: 204.9703 | AN19: -0.027992908 | AO19: 0 | AP19: #VALUE! | AQ19: -6.2206463e-06 | AR19: 0.0070917858 | AS19: #VALUE! | AT19: 0 | AU19: #VALUE! | AV19: 0.052875494 | AW19: -0.21772262 | AX19: -0.054863457 | AY19: 0.0092065566 | AZ19: 0 | BA19: 0 | BB19: 0 | BC19: 0 | BD19: -2.6386522 | BE19: 0 | BF19: -6.374189 | BG19: -216.61409 | BH19: 19.458182 | BI19: -3.1225023e-17 | BJ19: 0.031103232 | BK19: 9.3309695e-05 | BL19: -9.3309695e-06 | BM19: 0 | BN19: -29.143728 | BO19: 0.031103232 | BP19: -24.664863 | BQ19: 0.14929551 | BR19: -0.69012773 | BS19: #VALUE! | BT19: 0 | BU19: 9.3309695e-05 | BV19: -0.065316786 | BW19: 0.14123138 | BX19: -0.0069999396 | BY19: 0 | BZ19: 0 | CA19: #VALUE! | CB19: 0 | CC19: 0 | CD19: 0 | CE19: 0 | CF19: 11.665899 | CG19: 0.4177164 | CH19: -1.337917 | CI19: 0.015551616 | CJ19: 0.42099637 | CK19: #VALUE! | CL19: 0 | CM19: 2.1772262e-07 | CN19: 1.2352426 | CO19: -0.021772262 | CP19: 0 | CQ19: #VALUE! | CR19: 0 | CS19: -0.0031103232 | CT19: -0.031103232 | CU19: 0 | CV19: 0 | CW19: 0 | CX19: #VALUE! | CY19: -0.062206463 | CZ19: 0 | DA19: 0 | DB19: -1.8279842 | DC19: 0 | DD19: 0 | DE19: 0.88322603 | DF19: #VALUE! | DG19: 0.083830581 | DH19: -1.555147 | DI19: #VALUE! | DJ19: 0 | DK19: -0.00034213555 | DL19: 0 | DM19: -134.36596 | DN19: 0 | DO19: 0.46028211 | DP19: #VALUE! | DQ19: 0 | DR19: -0.56699511 | DS19: -36.826226 | DT19: -9.0199372 | DU19: 0.24882585 | DV19: 0 | DW19: 0 | DX19: 0.4616481 | DY19: 38.336288 | DZ19: 0.093309695 | EA19: -89.546173 | EB19: 0 | EC19: 1.3996454 | ED19: -32.813909 | EE19: 0 | EF19: 0 | EG19: 0 | EH19: #VALUE! | EI19: #VALUE! | EJ19: #VALUE! | EK19: -5.0076203 | EL19: 7.5435819 | EM19: #VALUE! | EN19: -0.71537433 | EO19: #VALUE! | EP19: -0.12441293 | EQ19: -3.0008399 | ER19: 0 | ES19: -6.9752398 | ET19: -0.00099999137 | EU19: -1029.1911 | EV19: 0 | EW19: 1.5551616 | EX19: 0.41740537 | EY19: -2.3327424 | EZ19: 8.2734596 | FA19: #VALUE! | FB19: #VALUE! | FC19: 0.037417188 | FD19: 0.0081743336 | FE19: -0.33499711 | FF19: #VALUE! | FG19: 6.1988741 | FH19: -12.347983 | FI19: -275.35619 | FJ19: -2.5547925 | FK19: -56.191204 | FL19: #VALUE! | FM19: 45.72175 | FN19: 0 | FO19: #VALUE! | FP19: 0 | FQ19: 0 | FR19: -13.27797 | FS19: 4.6154085 | FT19: -1524.98 | FU19: -1541.4737
